ERROR || 2020-06-22 15:39:30,056 || log || Internal Server Error: /archives/tvseries/5/
Traceback (most recent call last):
  File "C:\Users\hardcase1\.virtualenvs\series-EAOB5IHD\lib\site-packages\django\core\handlers\exception.py", line 34, in inner
    response = get_response(request)
  File "C:\Users\hardcase1\.virtualenvs\series-EAOB5IHD\lib\site-packages\django\core\handlers\base.py", line 115, in _get_response
    response = self.process_exception_by_middleware(e, request)
  File "C:\Users\hardcase1\.virtualenvs\series-EAOB5IHD\lib\site-packages\django\core\handlers\base.py", line 113, in _get_response
    response = wrapped_callback(request, *callback_args, **callback_kwargs)
  File "C:\Users\hardcase1\.virtualenvs\series-EAOB5IHD\lib\site-packages\django\views\decorators\csrf.py", line 54, in wrapped_view
    return view_func(*args, **kwargs)
  File "C:\Users\hardcase1\.virtualenvs\series-EAOB5IHD\lib\site-packages\django\views\generic\base.py", line 71, in view
    return self.dispatch(request, *args, **kwargs)
  File "C:\Users\hardcase1\.virtualenvs\series-EAOB5IHD\lib\site-packages\rest_framework\views.py", line 505, in dispatch
    response = self.handle_exception(exc)
  File "C:\Users\hardcase1\.virtualenvs\series-EAOB5IHD\lib\site-packages\rest_framework\views.py", line 465, in handle_exception
    self.raise_uncaught_exception(exc)
  File "C:\Users\hardcase1\.virtualenvs\series-EAOB5IHD\lib\site-packages\rest_framework\views.py", line 476, in raise_uncaught_exception
    raise exc
  File "C:\Users\hardcase1\.virtualenvs\series-EAOB5IHD\lib\site-packages\rest_framework\views.py", line 502, in dispatch
    response = handler(request, *args, **kwargs)
  File "C:\Users\hardcase1\.virtualenvs\series-EAOB5IHD\lib\site-packages\rest_framework\generics.py", line 282, in get
    return self.retrieve(request, *args, **kwargs)
  File "C:\Users\hardcase1\.virtualenvs\series-EAOB5IHD\lib\site-packages\rest_framework\mixins.py", line 56, in retrieve
    return Response(serializer.data)
  File "C:\Users\hardcase1\.virtualenvs\series-EAOB5IHD\lib\site-packages\rest_framework\serializers.py", line 562, in data
    ret = super().data
  File "C:\Users\hardcase1\.virtualenvs\series-EAOB5IHD\lib\site-packages\rest_framework\serializers.py", line 260, in data
    self._data = self.to_representation(self.instance)
  File "C:\Users\hardcase1\PycharmProjects\series\series\helpers\serializer_mixins.py", line 104, in to_representation
    data = super().to_representation(instance)
  File "C:\Users\hardcase1\.virtualenvs\series-EAOB5IHD\lib\site-packages\rest_framework\serializers.py", line 529, in to_representation
    ret[field.field_name] = field.to_representation(attribute)
  File "C:\Users\hardcase1\.virtualenvs\series-EAOB5IHD\lib\site-packages\rest_framework\fields.py", line 1905, in to_representation
    return method(value)
  File "C:\Users\hardcase1\PycharmProjects\series\archives\serializers.py", line 153, in get_allowed_redactors
    slaves = obj.entry_author.my_slaves()
TypeError: 'UserQueryset' object is not callable
ERROR || 2020-06-22 15:39:30,290 || basehttp || "GET /archives/tvseries/5/ HTTP/1.1" 500 164972
ERROR || 2020-06-22 15:42:29,533 || log || Internal Server Error: /archives/tvseries/5/
Traceback (most recent call last):
  File "C:\Users\hardcase1\.virtualenvs\series-EAOB5IHD\lib\site-packages\django\core\handlers\exception.py", line 34, in inner
    response = get_response(request)
  File "C:\Users\hardcase1\.virtualenvs\series-EAOB5IHD\lib\site-packages\django\core\handlers\base.py", line 145, in _get_response
    response = self.process_exception_by_middleware(e, request)
  File "C:\Users\hardcase1\.virtualenvs\series-EAOB5IHD\lib\site-packages\django\core\handlers\base.py", line 143, in _get_response
    response = response.render()
  File "C:\Users\hardcase1\.virtualenvs\series-EAOB5IHD\lib\site-packages\django\template\response.py", line 105, in render
    self.content = self.rendered_content
  File "C:\Users\hardcase1\.virtualenvs\series-EAOB5IHD\lib\site-packages\rest_framework\response.py", line 70, in rendered_content
    ret = renderer.render(self.data, accepted_media_type, context)
  File "C:\Users\hardcase1\.virtualenvs\series-EAOB5IHD\lib\site-packages\rest_framework\renderers.py", line 724, in render
    context = self.get_context(data, accepted_media_type, renderer_context)
  File "C:\Users\hardcase1\.virtualenvs\series-EAOB5IHD\lib\site-packages\rest_framework\renderers.py", line 656, in get_context
    raw_data_put_form = self.get_raw_data_form(data, view, 'PUT', request)
  File "C:\Users\hardcase1\.virtualenvs\series-EAOB5IHD\lib\site-packages\rest_framework\renderers.py", line 567, in get_raw_data_form
    content = renderer.render(data, accepted, context)
  File "C:\Users\hardcase1\.virtualenvs\series-EAOB5IHD\lib\site-packages\rest_framework\renderers.py", line 100, in render
    ret = json.dumps(
  File "C:\Users\hardcase1\.virtualenvs\series-EAOB5IHD\lib\site-packages\rest_framework\utils\json.py", line 25, in dumps
    return json.dumps(*args, **kwargs)
  File "c:\python\lib\json\__init__.py", line 234, in dumps
    return cls(
  File "c:\python\lib\json\encoder.py", line 201, in encode
    chunks = list(chunks)
  File "c:\python\lib\json\encoder.py", line 431, in _iterencode
    yield from _iterencode_dict(o, _current_indent_level)
  File "c:\python\lib\json\encoder.py", line 405, in _iterencode_dict
    yield from chunks
  File "c:\python\lib\json\encoder.py", line 405, in _iterencode_dict
    yield from chunks
  File "c:\python\lib\json\encoder.py", line 439, in _iterencode
    yield from _iterencode(o, _current_indent_level)
  File "c:\python\lib\json\encoder.py", line 429, in _iterencode
    yield from _iterencode_list(o, _current_indent_level)
  File "c:\python\lib\json\encoder.py", line 325, in _iterencode_list
    yield from chunks
  File "c:\python\lib\json\encoder.py", line 438, in _iterencode
    o = _default(o)
  File "C:\Users\hardcase1\.virtualenvs\series-EAOB5IHD\lib\site-packages\rest_framework\utils\encoders.py", line 67, in default
    return super().default(obj)
  File "c:\python\lib\json\encoder.py", line 179, in default
    raise TypeError(f'Object of type {o.__class__.__name__} '
TypeError: Object of type User is not JSON serializable
ERROR || 2020-06-22 15:42:29,797 || basehttp || "GET /archives/tvseries/5/ HTTP/1.1" 500 220684
ERROR || 2020-06-22 15:43:39,954 || log || Internal Server Error: /archives/tvseries/5/
Traceback (most recent call last):
  File "C:\Users\hardcase1\.virtualenvs\series-EAOB5IHD\lib\site-packages\django\core\handlers\exception.py", line 34, in inner
    response = get_response(request)
  File "C:\Users\hardcase1\.virtualenvs\series-EAOB5IHD\lib\site-packages\django\core\handlers\base.py", line 115, in _get_response
    response = self.process_exception_by_middleware(e, request)
  File "C:\Users\hardcase1\.virtualenvs\series-EAOB5IHD\lib\site-packages\django\core\handlers\base.py", line 113, in _get_response
    response = wrapped_callback(request, *callback_args, **callback_kwargs)
  File "C:\Users\hardcase1\.virtualenvs\series-EAOB5IHD\lib\site-packages\django\views\decorators\csrf.py", line 54, in wrapped_view
    return view_func(*args, **kwargs)
  File "C:\Users\hardcase1\.virtualenvs\series-EAOB5IHD\lib\site-packages\django\views\generic\base.py", line 71, in view
    return self.dispatch(request, *args, **kwargs)
  File "C:\Users\hardcase1\.virtualenvs\series-EAOB5IHD\lib\site-packages\rest_framework\views.py", line 505, in dispatch
    response = self.handle_exception(exc)
  File "C:\Users\hardcase1\.virtualenvs\series-EAOB5IHD\lib\site-packages\rest_framework\views.py", line 465, in handle_exception
    self.raise_uncaught_exception(exc)
  File "C:\Users\hardcase1\.virtualenvs\series-EAOB5IHD\lib\site-packages\rest_framework\views.py", line 476, in raise_uncaught_exception
    raise exc
  File "C:\Users\hardcase1\.virtualenvs\series-EAOB5IHD\lib\site-packages\rest_framework\views.py", line 502, in dispatch
    response = handler(request, *args, **kwargs)
  File "C:\Users\hardcase1\.virtualenvs\series-EAOB5IHD\lib\site-packages\rest_framework\generics.py", line 282, in get
    return self.retrieve(request, *args, **kwargs)
  File "C:\Users\hardcase1\.virtualenvs\series-EAOB5IHD\lib\site-packages\rest_framework\mixins.py", line 56, in retrieve
    return Response(serializer.data)
  File "C:\Users\hardcase1\.virtualenvs\series-EAOB5IHD\lib\site-packages\rest_framework\serializers.py", line 562, in data
    ret = super().data
  File "C:\Users\hardcase1\.virtualenvs\series-EAOB5IHD\lib\site-packages\rest_framework\serializers.py", line 260, in data
    self._data = self.to_representation(self.instance)
  File "C:\Users\hardcase1\PycharmProjects\series\series\helpers\serializer_mixins.py", line 104, in to_representation
    data = super().to_representation(instance)
  File "C:\Users\hardcase1\.virtualenvs\series-EAOB5IHD\lib\site-packages\rest_framework\serializers.py", line 529, in to_representation
    ret[field.field_name] = field.to_representation(attribute)
  File "C:\Users\hardcase1\.virtualenvs\series-EAOB5IHD\lib\site-packages\rest_framework\fields.py", line 1905, in to_representation
    return method(value)
  File "C:\Users\hardcase1\PycharmProjects\series\archives\serializers.py", line 153, in get_allowed_redactors
    slaves = {slave.pk. slave.full_name for slave in obj.entry_author.my_slaves}
  File "C:\Users\hardcase1\PycharmProjects\series\archives\serializers.py", line 153, in <setcomp>
    slaves = {slave.pk. slave.full_name for slave in obj.entry_author.my_slaves}
AttributeError: 'int' object has no attribute 'slave'
ERROR || 2020-06-22 15:43:40,139 || basehttp || "GET /archives/tvseries/5/ HTTP/1.1" 500 169031
