WARNING || 2020-06-23 10:16:35,290 || log || Not Found: /favicon.ico
WARNING || 2020-06-23 10:16:35,291 || basehttp || "GET /favicon.ico HTTP/1.1" 404 12161
WARNING || 2020-06-23 10:31:25,004 || log || Forbidden: /archives/tvseries/34/delete-image/577,578/
WARNING || 2020-06-23 10:31:25,036 || log || Forbidden: /archives/tvseries/34/delete-image/581,582/
WARNING || 2020-06-23 10:31:25,051 || log || Bad Request: /archives/tvseries/34/delete-image/1000,999/
WARNING || 2020-06-23 10:31:25,098 || log || Bad Request: /archives/tvseries/36/upload-image/small_image.gif/
WARNING || 2020-06-23 10:31:30,908 || log || Not Found: /archives/tvseries/999/upload-image/test.jpg/
WARNING || 2020-06-23 10:31:31,527 || log || Bad Request: /auth/users/
WARNING || 2020-06-23 10:31:31,776 || log || Bad Request: /auth/users/confirm_undelete_account/
WARNING || 2020-06-23 10:31:32,247 || log || Bad Request: /auth/users/
WARNING || 2020-06-23 10:31:32,255 || log || Bad Request: /auth/users/
WARNING || 2020-06-23 10:31:32,264 || log || Bad Request: /auth/users/
WARNING || 2020-06-23 10:31:32,473 || log || Bad Request: /auth/users/
WARNING || 2020-06-23 10:31:32,473 || log || Bad Request: /auth/users/
WARNING || 2020-06-23 10:31:32,926 || log || Bad Request: /auth/jwt/create
WARNING || 2020-06-23 10:31:33,161 || log || Forbidden: /auth/users/master_slave_interchange/
WARNING || 2020-06-23 10:31:34,036 || log || Too Many Requests: /auth/users/master_slave_interchange/
WARNING || 2020-06-23 10:31:34,240 || log || Bad Request: /auth/users/master_slave_interchange/
WARNING || 2020-06-23 10:31:34,320 || log || Bad Request: /auth/jwt/refresh
WARNING || 2020-06-23 10:31:34,347 || log || Unauthorized: /auth/jwt/refresh
WARNING || 2020-06-23 10:31:34,819 || log || Bad Request: /auth/users/set_slaves/
WARNING || 2020-06-23 10:31:35,191 || log || Bad Request: /auth/users/set_slaves/
WARNING || 2020-06-23 10:31:35,556 || log || Bad Request: /auth/users/set_slaves/
WARNING || 2020-06-23 10:31:35,618 || log || Forbidden: /auth/users/resend_activation/
WARNING || 2020-06-23 10:31:35,634 || log || Forbidden: /auth/users/resend_activation/
WARNING || 2020-06-23 10:31:35,697 || log || Too Many Requests: /auth/users/resend_activation/
WARNING || 2020-06-23 10:31:36,181 || log || Too Many Requests: /auth/users/undelete_account/
WARNING || 2020-06-23 10:31:36,541 || log || Bad Request: /auth/users/undelete_account/
WARNING || 2020-06-23 12:05:06,171 || log || Forbidden: /archives/tvseries/5/
WARNING || 2020-06-23 12:05:06,172 || basehttp || "GET /archives/tvseries/5/ HTTP/1.1" 403 14267
WARNING || 2020-06-23 12:05:09,326 || log || Forbidden: /archives/tvseries/5/
WARNING || 2020-06-23 12:05:09,326 || basehttp || "GET /archives/tvseries/5/ HTTP/1.1" 403 14267
WARNING || 2020-06-23 12:06:54,468 || log || Forbidden: /archives/tvseries/5/
WARNING || 2020-06-23 12:06:54,468 || basehttp || "GET /archives/tvseries/5/ HTTP/1.1" 403 14267
WARNING || 2020-06-23 12:08:42,340 || log || Forbidden: /archives/tvseries/5/
WARNING || 2020-06-23 12:08:42,341 || basehttp || "GET /archives/tvseries/5/ HTTP/1.1" 403 14267
ERROR || 2020-06-23 12:08:51,817 || log || Internal Server Error: /archives/tvseries/5/
Traceback (most recent call last):
  File "C:\Users\hardcase1\.virtualenvs\series-EAOB5IHD\lib\site-packages\django\core\handlers\exception.py", line 34, in inner
    response = get_response(request)
  File "C:\Users\hardcase1\.virtualenvs\series-EAOB5IHD\lib\site-packages\django\core\handlers\base.py", line 145, in _get_response
    response = self.process_exception_by_middleware(e, request)
  File "C:\Users\hardcase1\.virtualenvs\series-EAOB5IHD\lib\site-packages\django\core\handlers\base.py", line 143, in _get_response
    response = response.render()
  File "C:\Users\hardcase1\.virtualenvs\series-EAOB5IHD\lib\site-packages\django\template\response.py", line 105, in render
    self.content = self.rendered_content
  File "C:\Users\hardcase1\.virtualenvs\series-EAOB5IHD\lib\site-packages\rest_framework\response.py", line 70, in rendered_content
    ret = renderer.render(self.data, accepted_media_type, context)
  File "C:\Users\hardcase1\.virtualenvs\series-EAOB5IHD\lib\site-packages\rest_framework\renderers.py", line 724, in render
    context = self.get_context(data, accepted_media_type, renderer_context)
  File "C:\Users\hardcase1\.virtualenvs\series-EAOB5IHD\lib\site-packages\rest_framework\renderers.py", line 656, in get_context
    raw_data_put_form = self.get_raw_data_form(data, view, 'PUT', request)
  File "C:\Users\hardcase1\.virtualenvs\series-EAOB5IHD\lib\site-packages\rest_framework\renderers.py", line 563, in get_raw_data_form
    data = serializer.data.copy()
  File "C:\Users\hardcase1\.virtualenvs\series-EAOB5IHD\lib\site-packages\rest_framework\serializers.py", line 562, in data
    ret = super().data
  File "C:\Users\hardcase1\.virtualenvs\series-EAOB5IHD\lib\site-packages\rest_framework\serializers.py", line 264, in data
    self._data = self.get_initial()
  File "C:\Users\hardcase1\.virtualenvs\series-EAOB5IHD\lib\site-packages\rest_framework\serializers.py", line 412, in get_initial
    for field in self.fields.values()
  File "C:\Users\hardcase1\.virtualenvs\series-EAOB5IHD\lib\site-packages\django\utils\functional.py", line 48, in __get__
    res = instance.__dict__[self.name] = self.func(instance)
  File "C:\Users\hardcase1\.virtualenvs\series-EAOB5IHD\lib\site-packages\rest_framework\serializers.py", line 363, in fields
    for key, value in self.get_fields().items():
  File "C:\Users\hardcase1\PycharmProjects\series\archives\serializers.py", line 164, in get_fields
    entry_author = self.context['view'].obj.entry_author
AttributeError: 'TvSeriesDetailView' object has no attribute 'obj'
ERROR || 2020-06-23 12:08:51,947 || basehttp || "GET /archives/tvseries/5/ HTTP/1.1" 500 143044
WARNING || 2020-06-23 12:10:40,051 || log || Forbidden: /archives/tvseries/5/
WARNING || 2020-06-23 12:10:40,052 || basehttp || "GET /archives/tvseries/5/ HTTP/1.1" 403 15902
WARNING || 2020-06-23 12:21:29,566 || log || Forbidden: /archives/tvseries/5/
WARNING || 2020-06-23 12:21:29,567 || basehttp || "GET /archives/tvseries/5/ HTTP/1.1" 403 14267
WARNING || 2020-06-23 12:22:02,386 || log || Forbidden: /archives/tvseries/5/
WARNING || 2020-06-23 12:22:02,386 || basehttp || "GET /archives/tvseries/5/ HTTP/1.1" 403 14267
WARNING || 2020-06-23 12:22:35,734 || log || Forbidden: /archives/tvseries/19/delete-image/618,619/
WARNING || 2020-06-23 12:22:35,766 || log || Forbidden: /archives/tvseries/19/delete-image/622,623/
WARNING || 2020-06-23 12:22:35,783 || log || Bad Request: /archives/tvseries/19/delete-image/1000,999/
WARNING || 2020-06-23 12:22:35,845 || log || Bad Request: /archives/tvseries/21/upload-image/small_image.gif/
WARNING || 2020-06-23 12:22:59,775 || log || Forbidden: /archives/tvseries/5/
WARNING || 2020-06-23 12:22:59,776 || basehttp || "GET /archives/tvseries/5/ HTTP/1.1" 403 14267
ERROR || 2020-06-23 12:35:32,949 || log || Internal Server Error: /archives/tvseries/5/
Traceback (most recent call last):
  File "C:\Users\hardcase1\.virtualenvs\series-EAOB5IHD\lib\site-packages\django\core\handlers\exception.py", line 34, in inner
    response = get_response(request)
  File "C:\Users\hardcase1\.virtualenvs\series-EAOB5IHD\lib\site-packages\django\core\handlers\base.py", line 115, in _get_response
    response = self.process_exception_by_middleware(e, request)
  File "C:\Users\hardcase1\.virtualenvs\series-EAOB5IHD\lib\site-packages\django\core\handlers\base.py", line 113, in _get_response
    response = wrapped_callback(request, *callback_args, **callback_kwargs)
  File "C:\Users\hardcase1\.virtualenvs\series-EAOB5IHD\lib\site-packages\django\views\decorators\csrf.py", line 54, in wrapped_view
    return view_func(*args, **kwargs)
  File "C:\Users\hardcase1\.virtualenvs\series-EAOB5IHD\lib\site-packages\django\views\generic\base.py", line 62, in view
    self = cls(**initkwargs)
  File "C:\Users\hardcase1\PycharmProjects\series\archives\views.py", line 64, in __init__
    self.obj = super().get_object()
  File "C:\Users\hardcase1\.virtualenvs\series-EAOB5IHD\lib\site-packages\rest_framework\generics.py", line 88, in get_object
    assert lookup_url_kwarg in self.kwargs, (
AttributeError: 'TvSeriesDetailView' object has no attribute 'kwargs'
ERROR || 2020-06-23 12:35:33,064 || basehttp || "GET /archives/tvseries/5/ HTTP/1.1" 500 107528
ERROR || 2020-06-23 12:39:27,425 || log || Internal Server Error: /archives/tvseries/5/
Traceback (most recent call last):
  File "C:\Users\hardcase1\.virtualenvs\series-EAOB5IHD\lib\site-packages\django\core\handlers\exception.py", line 34, in inner
    response = get_response(request)
  File "C:\Users\hardcase1\.virtualenvs\series-EAOB5IHD\lib\site-packages\django\core\handlers\base.py", line 115, in _get_response
    response = self.process_exception_by_middleware(e, request)
  File "C:\Users\hardcase1\.virtualenvs\series-EAOB5IHD\lib\site-packages\django\core\handlers\base.py", line 113, in _get_response
    response = wrapped_callback(request, *callback_args, **callback_kwargs)
  File "C:\Users\hardcase1\.virtualenvs\series-EAOB5IHD\lib\site-packages\django\views\decorators\csrf.py", line 54, in wrapped_view
    return view_func(*args, **kwargs)
  File "C:\Users\hardcase1\.virtualenvs\series-EAOB5IHD\lib\site-packages\django\views\generic\base.py", line 71, in view
    return self.dispatch(request, *args, **kwargs)
  File "C:\Users\hardcase1\.virtualenvs\series-EAOB5IHD\lib\site-packages\rest_framework\views.py", line 505, in dispatch
    response = self.handle_exception(exc)
  File "C:\Users\hardcase1\.virtualenvs\series-EAOB5IHD\lib\site-packages\rest_framework\views.py", line 465, in handle_exception
    self.raise_uncaught_exception(exc)
  File "C:\Users\hardcase1\.virtualenvs\series-EAOB5IHD\lib\site-packages\rest_framework\views.py", line 476, in raise_uncaught_exception
    raise exc
  File "C:\Users\hardcase1\.virtualenvs\series-EAOB5IHD\lib\site-packages\rest_framework\views.py", line 502, in dispatch
    response = handler(request, *args, **kwargs)
  File "C:\Users\hardcase1\.virtualenvs\series-EAOB5IHD\lib\site-packages\rest_framework\generics.py", line 282, in get
    return self.retrieve(request, *args, **kwargs)
  File "C:\Users\hardcase1\.virtualenvs\series-EAOB5IHD\lib\site-packages\rest_framework\mixins.py", line 54, in retrieve
    instance = self.get_object()
TypeError: 'TvSeriesModel' object is not callable
ERROR || 2020-06-23 12:39:27,526 || basehttp || "GET /archives/tvseries/5/ HTTP/1.1" 500 125146
ERROR || 2020-06-23 12:39:48,404 || log || Internal Server Error: /archives/tvseries/5/
Traceback (most recent call last):
  File "C:\Users\hardcase1\.virtualenvs\series-EAOB5IHD\lib\site-packages\django\core\handlers\exception.py", line 34, in inner
    response = get_response(request)
  File "C:\Users\hardcase1\.virtualenvs\series-EAOB5IHD\lib\site-packages\django\core\handlers\base.py", line 115, in _get_response
    response = self.process_exception_by_middleware(e, request)
  File "C:\Users\hardcase1\.virtualenvs\series-EAOB5IHD\lib\site-packages\django\core\handlers\base.py", line 113, in _get_response
    response = wrapped_callback(request, *callback_args, **callback_kwargs)
  File "C:\Users\hardcase1\.virtualenvs\series-EAOB5IHD\lib\site-packages\django\views\decorators\csrf.py", line 54, in wrapped_view
    return view_func(*args, **kwargs)
  File "C:\Users\hardcase1\.virtualenvs\series-EAOB5IHD\lib\site-packages\django\views\generic\base.py", line 71, in view
    return self.dispatch(request, *args, **kwargs)
  File "C:\Users\hardcase1\.virtualenvs\series-EAOB5IHD\lib\site-packages\rest_framework\views.py", line 505, in dispatch
    response = self.handle_exception(exc)
  File "C:\Users\hardcase1\.virtualenvs\series-EAOB5IHD\lib\site-packages\rest_framework\views.py", line 465, in handle_exception
    self.raise_uncaught_exception(exc)
  File "C:\Users\hardcase1\.virtualenvs\series-EAOB5IHD\lib\site-packages\rest_framework\views.py", line 476, in raise_uncaught_exception
    raise exc
  File "C:\Users\hardcase1\.virtualenvs\series-EAOB5IHD\lib\site-packages\rest_framework\views.py", line 502, in dispatch
    response = handler(request, *args, **kwargs)
  File "C:\Users\hardcase1\.virtualenvs\series-EAOB5IHD\lib\site-packages\rest_framework\generics.py", line 282, in get
    return self.retrieve(request, *args, **kwargs)
  File "C:\Users\hardcase1\.virtualenvs\series-EAOB5IHD\lib\site-packages\rest_framework\mixins.py", line 54, in retrieve
    instance = self.get_object()
TypeError: 'TvSeriesModel' object is not callable
ERROR || 2020-06-23 12:39:48,525 || basehttp || "GET /archives/tvseries/5/ HTTP/1.1" 500 125015
ERROR || 2020-06-23 12:46:06,872 || log || Internal Server Error: /archives/tvseries/5/
Traceback (most recent call last):
  File "C:\Users\hardcase1\.virtualenvs\series-EAOB5IHD\lib\site-packages\django\core\handlers\exception.py", line 34, in inner
    response = get_response(request)
  File "C:\Users\hardcase1\.virtualenvs\series-EAOB5IHD\lib\site-packages\django\core\handlers\base.py", line 115, in _get_response
    response = self.process_exception_by_middleware(e, request)
  File "C:\Users\hardcase1\.virtualenvs\series-EAOB5IHD\lib\site-packages\django\core\handlers\base.py", line 113, in _get_response
    response = wrapped_callback(request, *callback_args, **callback_kwargs)
  File "C:\Users\hardcase1\.virtualenvs\series-EAOB5IHD\lib\site-packages\django\views\decorators\csrf.py", line 54, in wrapped_view
    return view_func(*args, **kwargs)
  File "C:\Users\hardcase1\.virtualenvs\series-EAOB5IHD\lib\site-packages\django\views\generic\base.py", line 71, in view
    return self.dispatch(request, *args, **kwargs)
  File "C:\Users\hardcase1\.virtualenvs\series-EAOB5IHD\lib\site-packages\rest_framework\views.py", line 505, in dispatch
    response = self.handle_exception(exc)
  File "C:\Users\hardcase1\.virtualenvs\series-EAOB5IHD\lib\site-packages\rest_framework\views.py", line 465, in handle_exception
    self.raise_uncaught_exception(exc)
  File "C:\Users\hardcase1\.virtualenvs\series-EAOB5IHD\lib\site-packages\rest_framework\views.py", line 476, in raise_uncaught_exception
    raise exc
  File "C:\Users\hardcase1\.virtualenvs\series-EAOB5IHD\lib\site-packages\rest_framework\views.py", line 502, in dispatch
    response = handler(request, *args, **kwargs)
  File "C:\Users\hardcase1\.virtualenvs\series-EAOB5IHD\lib\site-packages\rest_framework\generics.py", line 282, in get
    return self.retrieve(request, *args, **kwargs)
  File "C:\Users\hardcase1\.virtualenvs\series-EAOB5IHD\lib\site-packages\rest_framework\mixins.py", line 56, in retrieve
    return Response(serializer.data)
  File "C:\Users\hardcase1\.virtualenvs\series-EAOB5IHD\lib\site-packages\rest_framework\serializers.py", line 562, in data
    ret = super().data
  File "C:\Users\hardcase1\.virtualenvs\series-EAOB5IHD\lib\site-packages\rest_framework\serializers.py", line 260, in data
    self._data = self.to_representation(self.instance)
  File "C:\Users\hardcase1\PycharmProjects\series\series\helpers\serializer_mixins.py", line 147, in to_representation
    data = super().to_representation(instance)
  File "C:\Users\hardcase1\.virtualenvs\series-EAOB5IHD\lib\site-packages\rest_framework\serializers.py", line 529, in to_representation
    ret[field.field_name] = field.to_representation(attribute)
  File "C:\Users\hardcase1\.virtualenvs\series-EAOB5IHD\lib\site-packages\rest_framework\fields.py", line 1905, in to_representation
    return method(value)
  File "C:\Users\hardcase1\PycharmProjects\series\archives\serializers.py", line 163, in get_allowed_redactors
    return custom_functions.dict_from_names('master', 'friends', 'slaves')
  File "C:\Users\hardcase1\PycharmProjects\series\series\helpers\custom_functions.py", line 78, in dict_from_names
    return {name: namespace[name] for name in variable_names}
  File "C:\Users\hardcase1\PycharmProjects\series\series\helpers\custom_functions.py", line 78, in <dictcomp>
    return {name: namespace[name] for name in variable_names}
KeyError: 'master'
ERROR || 2020-06-23 12:46:07,047 || basehttp || "GET /archives/tvseries/5/ HTTP/1.1" 500 180329
ERROR || 2020-06-23 12:46:51,784 || log || Internal Server Error: /archives/tvseries/5/
Traceback (most recent call last):
  File "C:\Users\hardcase1\.virtualenvs\series-EAOB5IHD\lib\site-packages\django\core\handlers\exception.py", line 34, in inner
    response = get_response(request)
  File "C:\Users\hardcase1\.virtualenvs\series-EAOB5IHD\lib\site-packages\django\core\handlers\base.py", line 115, in _get_response
    response = self.process_exception_by_middleware(e, request)
  File "C:\Users\hardcase1\.virtualenvs\series-EAOB5IHD\lib\site-packages\django\core\handlers\base.py", line 113, in _get_response
    response = wrapped_callback(request, *callback_args, **callback_kwargs)
  File "C:\Users\hardcase1\.virtualenvs\series-EAOB5IHD\lib\site-packages\django\views\decorators\csrf.py", line 54, in wrapped_view
    return view_func(*args, **kwargs)
  File "C:\Users\hardcase1\.virtualenvs\series-EAOB5IHD\lib\site-packages\django\views\generic\base.py", line 71, in view
    return self.dispatch(request, *args, **kwargs)
  File "C:\Users\hardcase1\.virtualenvs\series-EAOB5IHD\lib\site-packages\rest_framework\views.py", line 505, in dispatch
    response = self.handle_exception(exc)
  File "C:\Users\hardcase1\.virtualenvs\series-EAOB5IHD\lib\site-packages\rest_framework\views.py", line 465, in handle_exception
    self.raise_uncaught_exception(exc)
  File "C:\Users\hardcase1\.virtualenvs\series-EAOB5IHD\lib\site-packages\rest_framework\views.py", line 476, in raise_uncaught_exception
    raise exc
  File "C:\Users\hardcase1\.virtualenvs\series-EAOB5IHD\lib\site-packages\rest_framework\views.py", line 502, in dispatch
    response = handler(request, *args, **kwargs)
  File "C:\Users\hardcase1\.virtualenvs\series-EAOB5IHD\lib\site-packages\rest_framework\generics.py", line 282, in get
    return self.retrieve(request, *args, **kwargs)
  File "C:\Users\hardcase1\.virtualenvs\series-EAOB5IHD\lib\site-packages\rest_framework\mixins.py", line 56, in retrieve
    return Response(serializer.data)
  File "C:\Users\hardcase1\.virtualenvs\series-EAOB5IHD\lib\site-packages\rest_framework\serializers.py", line 562, in data
    ret = super().data
  File "C:\Users\hardcase1\.virtualenvs\series-EAOB5IHD\lib\site-packages\rest_framework\serializers.py", line 260, in data
    self._data = self.to_representation(self.instance)
  File "C:\Users\hardcase1\PycharmProjects\series\series\helpers\serializer_mixins.py", line 147, in to_representation
    data = super().to_representation(instance)
  File "C:\Users\hardcase1\.virtualenvs\series-EAOB5IHD\lib\site-packages\rest_framework\serializers.py", line 529, in to_representation
    ret[field.field_name] = field.to_representation(attribute)
  File "C:\Users\hardcase1\.virtualenvs\series-EAOB5IHD\lib\site-packages\rest_framework\fields.py", line 1905, in to_representation
    return method(value)
  File "C:\Users\hardcase1\PycharmProjects\series\archives\serializers.py", line 163, in get_allowed_redactors
    return custom_functions.dict_from_names('master', 'friends', 'slaves', namespace=locals)
  File "C:\Users\hardcase1\PycharmProjects\series\series\helpers\custom_functions.py", line 78, in dict_from_names
    return {name: namespace[name] for name in variable_names}
  File "C:\Users\hardcase1\PycharmProjects\series\series\helpers\custom_functions.py", line 78, in <dictcomp>
    return {name: namespace[name] for name in variable_names}
KeyError: 'master'
ERROR || 2020-06-23 12:46:51,953 || basehttp || "GET /archives/tvseries/5/ HTTP/1.1" 500 169067
ERROR || 2020-06-23 12:46:54,322 || log || Internal Server Error: /archives/tvseries/5/
Traceback (most recent call last):
  File "C:\Users\hardcase1\.virtualenvs\series-EAOB5IHD\lib\site-packages\django\core\handlers\exception.py", line 34, in inner
    response = get_response(request)
  File "C:\Users\hardcase1\.virtualenvs\series-EAOB5IHD\lib\site-packages\django\core\handlers\base.py", line 115, in _get_response
    response = self.process_exception_by_middleware(e, request)
  File "C:\Users\hardcase1\.virtualenvs\series-EAOB5IHD\lib\site-packages\django\core\handlers\base.py", line 113, in _get_response
    response = wrapped_callback(request, *callback_args, **callback_kwargs)
  File "C:\Users\hardcase1\.virtualenvs\series-EAOB5IHD\lib\site-packages\django\views\decorators\csrf.py", line 54, in wrapped_view
    return view_func(*args, **kwargs)
  File "C:\Users\hardcase1\.virtualenvs\series-EAOB5IHD\lib\site-packages\django\views\generic\base.py", line 71, in view
    return self.dispatch(request, *args, **kwargs)
  File "C:\Users\hardcase1\.virtualenvs\series-EAOB5IHD\lib\site-packages\rest_framework\views.py", line 505, in dispatch
    response = self.handle_exception(exc)
  File "C:\Users\hardcase1\.virtualenvs\series-EAOB5IHD\lib\site-packages\rest_framework\views.py", line 465, in handle_exception
    self.raise_uncaught_exception(exc)
  File "C:\Users\hardcase1\.virtualenvs\series-EAOB5IHD\lib\site-packages\rest_framework\views.py", line 476, in raise_uncaught_exception
    raise exc
  File "C:\Users\hardcase1\.virtualenvs\series-EAOB5IHD\lib\site-packages\rest_framework\views.py", line 502, in dispatch
    response = handler(request, *args, **kwargs)
  File "C:\Users\hardcase1\.virtualenvs\series-EAOB5IHD\lib\site-packages\rest_framework\generics.py", line 282, in get
    return self.retrieve(request, *args, **kwargs)
  File "C:\Users\hardcase1\.virtualenvs\series-EAOB5IHD\lib\site-packages\rest_framework\mixins.py", line 56, in retrieve
    return Response(serializer.data)
  File "C:\Users\hardcase1\.virtualenvs\series-EAOB5IHD\lib\site-packages\rest_framework\serializers.py", line 562, in data
    ret = super().data
  File "C:\Users\hardcase1\.virtualenvs\series-EAOB5IHD\lib\site-packages\rest_framework\serializers.py", line 260, in data
    self._data = self.to_representation(self.instance)
  File "C:\Users\hardcase1\PycharmProjects\series\series\helpers\serializer_mixins.py", line 147, in to_representation
    data = super().to_representation(instance)
  File "C:\Users\hardcase1\.virtualenvs\series-EAOB5IHD\lib\site-packages\rest_framework\serializers.py", line 529, in to_representation
    ret[field.field_name] = field.to_representation(attribute)
  File "C:\Users\hardcase1\.virtualenvs\series-EAOB5IHD\lib\site-packages\rest_framework\fields.py", line 1905, in to_representation
    return method(value)
  File "C:\Users\hardcase1\PycharmProjects\series\archives\serializers.py", line 163, in get_allowed_redactors
    return custom_functions.dict_from_names('master', 'friends', 'slaves', namespace=locals)
  File "C:\Users\hardcase1\PycharmProjects\series\series\helpers\custom_functions.py", line 78, in dict_from_names
    return {name: namespace[name] for name in variable_names}
  File "C:\Users\hardcase1\PycharmProjects\series\series\helpers\custom_functions.py", line 78, in <dictcomp>
    return {name: namespace[name] for name in variable_names}
KeyError: 'master'
ERROR || 2020-06-23 12:46:54,480 || basehttp || "GET /archives/tvseries/5/ HTTP/1.1" 500 169066
WARNING || 2020-06-23 13:39:22,521 || log || Forbidden: /archives/tvseries/6/
WARNING || 2020-06-23 13:39:22,522 || basehttp || "GET /archives/tvseries/6/ HTTP/1.1" 403 14267
ERROR || 2020-06-23 13:44:21,050 || log || Internal Server Error: /archives/tvseries/6/
Traceback (most recent call last):
  File "C:\Users\hardcase1\.virtualenvs\series-EAOB5IHD\lib\site-packages\django\core\handlers\exception.py", line 34, in inner
    response = get_response(request)
  File "C:\Users\hardcase1\.virtualenvs\series-EAOB5IHD\lib\site-packages\django\core\handlers\base.py", line 115, in _get_response
    response = self.process_exception_by_middleware(e, request)
  File "C:\Users\hardcase1\.virtualenvs\series-EAOB5IHD\lib\site-packages\django\core\handlers\base.py", line 113, in _get_response
    response = wrapped_callback(request, *callback_args, **callback_kwargs)
  File "C:\Users\hardcase1\.virtualenvs\series-EAOB5IHD\lib\site-packages\django\views\decorators\csrf.py", line 54, in wrapped_view
    return view_func(*args, **kwargs)
  File "C:\Users\hardcase1\.virtualenvs\series-EAOB5IHD\lib\site-packages\django\views\generic\base.py", line 71, in view
    return self.dispatch(request, *args, **kwargs)
  File "C:\Users\hardcase1\.virtualenvs\series-EAOB5IHD\lib\site-packages\rest_framework\views.py", line 505, in dispatch
    response = self.handle_exception(exc)
  File "C:\Users\hardcase1\.virtualenvs\series-EAOB5IHD\lib\site-packages\rest_framework\views.py", line 465, in handle_exception
    self.raise_uncaught_exception(exc)
  File "C:\Users\hardcase1\.virtualenvs\series-EAOB5IHD\lib\site-packages\rest_framework\views.py", line 476, in raise_uncaught_exception
    raise exc
  File "C:\Users\hardcase1\.virtualenvs\series-EAOB5IHD\lib\site-packages\rest_framework\views.py", line 502, in dispatch
    response = handler(request, *args, **kwargs)
  File "C:\Users\hardcase1\.virtualenvs\series-EAOB5IHD\lib\site-packages\rest_framework\generics.py", line 282, in get
    return self.retrieve(request, *args, **kwargs)
  File "C:\Users\hardcase1\.virtualenvs\series-EAOB5IHD\lib\site-packages\rest_framework\mixins.py", line 56, in retrieve
    return Response(serializer.data)
  File "C:\Users\hardcase1\.virtualenvs\series-EAOB5IHD\lib\site-packages\rest_framework\serializers.py", line 562, in data
    ret = super().data
  File "C:\Users\hardcase1\.virtualenvs\series-EAOB5IHD\lib\site-packages\rest_framework\serializers.py", line 260, in data
    self._data = self.to_representation(self.instance)
  File "C:\Users\hardcase1\PycharmProjects\series\series\helpers\serializer_mixins.py", line 147, in to_representation
    data = super().to_representation(instance)
  File "C:\Users\hardcase1\.virtualenvs\series-EAOB5IHD\lib\site-packages\rest_framework\serializers.py", line 514, in to_representation
    for field in fields:
  File "C:\Users\hardcase1\.virtualenvs\series-EAOB5IHD\lib\site-packages\rest_framework\serializers.py", line 375, in _readable_fields
    for field in self.fields.values():
  File "C:\Users\hardcase1\.virtualenvs\series-EAOB5IHD\lib\site-packages\django\utils\functional.py", line 48, in __get__
    res = instance.__dict__[self.name] = self.func(instance)
  File "C:\Users\hardcase1\.virtualenvs\series-EAOB5IHD\lib\site-packages\rest_framework\serializers.py", line 363, in fields
    for key, value in self.get_fields().items():
  File "C:\Users\hardcase1\PycharmProjects\series\archives\serializers.py", line 186, in get_fields
    assert request.user.is_staff
AssertionError
ERROR || 2020-06-23 13:44:21,253 || basehttp || "GET /archives/tvseries/6/ HTTP/1.1" 500 158629
ERROR || 2020-06-23 13:44:34,807 || log || Internal Server Error: /archives/tvseries/6/
Traceback (most recent call last):
  File "C:\Users\hardcase1\.virtualenvs\series-EAOB5IHD\lib\site-packages\django\core\handlers\exception.py", line 34, in inner
    response = get_response(request)
  File "C:\Users\hardcase1\.virtualenvs\series-EAOB5IHD\lib\site-packages\django\core\handlers\base.py", line 115, in _get_response
    response = self.process_exception_by_middleware(e, request)
  File "C:\Users\hardcase1\.virtualenvs\series-EAOB5IHD\lib\site-packages\django\core\handlers\base.py", line 113, in _get_response
    response = wrapped_callback(request, *callback_args, **callback_kwargs)
  File "C:\Users\hardcase1\.virtualenvs\series-EAOB5IHD\lib\site-packages\django\views\decorators\csrf.py", line 54, in wrapped_view
    return view_func(*args, **kwargs)
  File "C:\Users\hardcase1\.virtualenvs\series-EAOB5IHD\lib\site-packages\django\views\generic\base.py", line 71, in view
    return self.dispatch(request, *args, **kwargs)
  File "C:\Users\hardcase1\.virtualenvs\series-EAOB5IHD\lib\site-packages\rest_framework\views.py", line 505, in dispatch
    response = self.handle_exception(exc)
  File "C:\Users\hardcase1\.virtualenvs\series-EAOB5IHD\lib\site-packages\rest_framework\views.py", line 465, in handle_exception
    self.raise_uncaught_exception(exc)
  File "C:\Users\hardcase1\.virtualenvs\series-EAOB5IHD\lib\site-packages\rest_framework\views.py", line 476, in raise_uncaught_exception
    raise exc
  File "C:\Users\hardcase1\.virtualenvs\series-EAOB5IHD\lib\site-packages\rest_framework\views.py", line 502, in dispatch
    response = handler(request, *args, **kwargs)
  File "C:\Users\hardcase1\.virtualenvs\series-EAOB5IHD\lib\site-packages\rest_framework\generics.py", line 282, in get
    return self.retrieve(request, *args, **kwargs)
  File "C:\Users\hardcase1\.virtualenvs\series-EAOB5IHD\lib\site-packages\rest_framework\mixins.py", line 56, in retrieve
    return Response(serializer.data)
  File "C:\Users\hardcase1\.virtualenvs\series-EAOB5IHD\lib\site-packages\rest_framework\serializers.py", line 562, in data
    ret = super().data
  File "C:\Users\hardcase1\.virtualenvs\series-EAOB5IHD\lib\site-packages\rest_framework\serializers.py", line 260, in data
    self._data = self.to_representation(self.instance)
  File "C:\Users\hardcase1\PycharmProjects\series\series\helpers\serializer_mixins.py", line 147, in to_representation
    data = super().to_representation(instance)
  File "C:\Users\hardcase1\.virtualenvs\series-EAOB5IHD\lib\site-packages\rest_framework\serializers.py", line 514, in to_representation
    for field in fields:
  File "C:\Users\hardcase1\.virtualenvs\series-EAOB5IHD\lib\site-packages\rest_framework\serializers.py", line 375, in _readable_fields
    for field in self.fields.values():
  File "C:\Users\hardcase1\.virtualenvs\series-EAOB5IHD\lib\site-packages\django\utils\functional.py", line 48, in __get__
    res = instance.__dict__[self.name] = self.func(instance)
  File "C:\Users\hardcase1\.virtualenvs\series-EAOB5IHD\lib\site-packages\rest_framework\serializers.py", line 363, in fields
    for key, value in self.get_fields().items():
  File "C:\Users\hardcase1\PycharmProjects\series\archives\serializers.py", line 186, in get_fields
    assert request.user.is_staff()
TypeError: 'bool' object is not callable
ERROR || 2020-06-23 13:44:34,962 || basehttp || "GET /archives/tvseries/6/ HTTP/1.1" 500 159317
WARNING || 2020-06-23 13:46:00,782 || log || Forbidden: /archives/tvseries/6/
WARNING || 2020-06-23 13:46:00,786 || basehttp || "GET /archives/tvseries/6/ HTTP/1.1" 403 14267
ERROR || 2020-06-23 13:46:07,307 || log || Internal Server Error: /archives/tvseries/6/
Traceback (most recent call last):
  File "C:\Users\hardcase1\.virtualenvs\series-EAOB5IHD\lib\site-packages\django\core\handlers\exception.py", line 34, in inner
    response = get_response(request)
  File "C:\Users\hardcase1\.virtualenvs\series-EAOB5IHD\lib\site-packages\django\core\handlers\base.py", line 115, in _get_response
    response = self.process_exception_by_middleware(e, request)
  File "C:\Users\hardcase1\.virtualenvs\series-EAOB5IHD\lib\site-packages\django\core\handlers\base.py", line 113, in _get_response
    response = wrapped_callback(request, *callback_args, **callback_kwargs)
  File "C:\Users\hardcase1\.virtualenvs\series-EAOB5IHD\lib\site-packages\django\views\decorators\csrf.py", line 54, in wrapped_view
    return view_func(*args, **kwargs)
  File "C:\Users\hardcase1\.virtualenvs\series-EAOB5IHD\lib\site-packages\django\views\generic\base.py", line 71, in view
    return self.dispatch(request, *args, **kwargs)
  File "C:\Users\hardcase1\.virtualenvs\series-EAOB5IHD\lib\site-packages\rest_framework\views.py", line 505, in dispatch
    response = self.handle_exception(exc)
  File "C:\Users\hardcase1\.virtualenvs\series-EAOB5IHD\lib\site-packages\rest_framework\views.py", line 465, in handle_exception
    self.raise_uncaught_exception(exc)
  File "C:\Users\hardcase1\.virtualenvs\series-EAOB5IHD\lib\site-packages\rest_framework\views.py", line 476, in raise_uncaught_exception
    raise exc
  File "C:\Users\hardcase1\.virtualenvs\series-EAOB5IHD\lib\site-packages\rest_framework\views.py", line 502, in dispatch
    response = handler(request, *args, **kwargs)
  File "C:\Users\hardcase1\.virtualenvs\series-EAOB5IHD\lib\site-packages\rest_framework\generics.py", line 282, in get
    return self.retrieve(request, *args, **kwargs)
  File "C:\Users\hardcase1\.virtualenvs\series-EAOB5IHD\lib\site-packages\rest_framework\mixins.py", line 56, in retrieve
    return Response(serializer.data)
  File "C:\Users\hardcase1\.virtualenvs\series-EAOB5IHD\lib\site-packages\rest_framework\serializers.py", line 562, in data
    ret = super().data
  File "C:\Users\hardcase1\.virtualenvs\series-EAOB5IHD\lib\site-packages\rest_framework\serializers.py", line 260, in data
    self._data = self.to_representation(self.instance)
  File "C:\Users\hardcase1\PycharmProjects\series\series\helpers\serializer_mixins.py", line 147, in to_representation
    data = super().to_representation(instance)
  File "C:\Users\hardcase1\.virtualenvs\series-EAOB5IHD\lib\site-packages\rest_framework\serializers.py", line 514, in to_representation
    for field in fields:
  File "C:\Users\hardcase1\.virtualenvs\series-EAOB5IHD\lib\site-packages\rest_framework\serializers.py", line 375, in _readable_fields
    for field in self.fields.values():
  File "C:\Users\hardcase1\.virtualenvs\series-EAOB5IHD\lib\site-packages\django\utils\functional.py", line 48, in __get__
    res = instance.__dict__[self.name] = self.func(instance)
  File "C:\Users\hardcase1\.virtualenvs\series-EAOB5IHD\lib\site-packages\rest_framework\serializers.py", line 363, in fields
    for key, value in self.get_fields().items():
  File "C:\Users\hardcase1\PycharmProjects\series\archives\serializers.py", line 186, in get_fields
    assert request.user == entry_author
AssertionError
ERROR || 2020-06-23 13:46:07,449 || basehttp || "GET /archives/tvseries/6/ HTTP/1.1" 500 158748
WARNING || 2020-06-23 13:48:08,693 || log || Forbidden: /archives/tvseries/6/
WARNING || 2020-06-23 13:48:08,694 || basehttp || "GET /archives/tvseries/6/ HTTP/1.1" 403 14267
WARNING || 2020-06-23 13:48:18,642 || log || Forbidden: /archives/tvseries/6/
WARNING || 2020-06-23 13:48:18,643 || basehttp || "GET /archives/tvseries/6/ HTTP/1.1" 403 14267
WARNING || 2020-06-23 13:48:28,357 || log || Forbidden: /archives/tvseries/6/
WARNING || 2020-06-23 13:48:28,358 || basehttp || "GET /archives/tvseries/6/ HTTP/1.1" 403 14267
WARNING || 2020-06-23 13:48:43,839 || log || Forbidden: /archives/tvseries/6/
WARNING || 2020-06-23 13:48:43,840 || basehttp || "GET /archives/tvseries/6/ HTTP/1.1" 403 14267
WARNING || 2020-06-23 13:59:12,680 || log || Forbidden: /archives/tvseries/6/
WARNING || 2020-06-23 13:59:12,681 || basehttp || "GET /archives/tvseries/6/ HTTP/1.1" 403 14267
WARNING || 2020-06-23 13:59:24,812 || log || Forbidden: /archives/tvseries/6/
WARNING || 2020-06-23 13:59:24,812 || basehttp || "GET /archives/tvseries/6/ HTTP/1.1" 403 14267
WARNING || 2020-06-23 13:59:48,170 || log || Forbidden: /archives/tvseries/6/
WARNING || 2020-06-23 13:59:48,170 || basehttp || "GET /archives/tvseries/6/ HTTP/1.1" 403 14267
ERROR || 2020-06-23 17:23:37,049 || log || Internal Server Error: /archives/tvseries/5/
Traceback (most recent call last):
  File "C:\Users\hardcase1\.virtualenvs\series-EAOB5IHD\lib\site-packages\django\core\handlers\exception.py", line 34, in inner
    response = get_response(request)
  File "C:\Users\hardcase1\.virtualenvs\series-EAOB5IHD\lib\site-packages\django\core\handlers\base.py", line 115, in _get_response
    response = self.process_exception_by_middleware(e, request)
  File "C:\Users\hardcase1\.virtualenvs\series-EAOB5IHD\lib\site-packages\django\core\handlers\base.py", line 113, in _get_response
    response = wrapped_callback(request, *callback_args, **callback_kwargs)
  File "C:\Users\hardcase1\.virtualenvs\series-EAOB5IHD\lib\site-packages\django\views\decorators\csrf.py", line 54, in wrapped_view
    return view_func(*args, **kwargs)
  File "C:\Users\hardcase1\.virtualenvs\series-EAOB5IHD\lib\site-packages\django\views\generic\base.py", line 71, in view
    return self.dispatch(request, *args, **kwargs)
  File "C:\Users\hardcase1\.virtualenvs\series-EAOB5IHD\lib\site-packages\rest_framework\views.py", line 505, in dispatch
    response = self.handle_exception(exc)
  File "C:\Users\hardcase1\.virtualenvs\series-EAOB5IHD\lib\site-packages\rest_framework\views.py", line 465, in handle_exception
    self.raise_uncaught_exception(exc)
  File "C:\Users\hardcase1\.virtualenvs\series-EAOB5IHD\lib\site-packages\rest_framework\views.py", line 476, in raise_uncaught_exception
    raise exc
  File "C:\Users\hardcase1\.virtualenvs\series-EAOB5IHD\lib\site-packages\rest_framework\views.py", line 502, in dispatch
    response = handler(request, *args, **kwargs)
  File "C:\Users\hardcase1\.virtualenvs\series-EAOB5IHD\lib\site-packages\rest_framework\generics.py", line 282, in get
    return self.retrieve(request, *args, **kwargs)
  File "C:\Users\hardcase1\.virtualenvs\series-EAOB5IHD\lib\site-packages\rest_framework\mixins.py", line 56, in retrieve
    return Response(serializer.data)
  File "C:\Users\hardcase1\.virtualenvs\series-EAOB5IHD\lib\site-packages\rest_framework\serializers.py", line 562, in data
    ret = super().data
  File "C:\Users\hardcase1\.virtualenvs\series-EAOB5IHD\lib\site-packages\rest_framework\serializers.py", line 260, in data
    self._data = self.to_representation(self.instance)
  File "C:\Users\hardcase1\PycharmProjects\series\series\helpers\serializer_mixins.py", line 147, in to_representation
    data = super().to_representation(instance)
  File "C:\Users\hardcase1\.virtualenvs\series-EAOB5IHD\lib\site-packages\rest_framework\serializers.py", line 529, in to_representation
    ret[field.field_name] = field.to_representation(attribute)
  File "C:\Users\hardcase1\.virtualenvs\series-EAOB5IHD\lib\site-packages\rest_framework\fields.py", line 1905, in to_representation
    return method(value)
  File "C:\Users\hardcase1\PycharmProjects\series\archives\serializers.py", line 176, in get_allowed_redactors
    slaves = {{'pk': slave.pk, 'name': slave.get_full_name()} for slave in obj.entry_author.slaves.all()} or None
  File "C:\Users\hardcase1\PycharmProjects\series\archives\serializers.py", line 176, in <setcomp>
    slaves = {{'pk': slave.pk, 'name': slave.get_full_name()} for slave in obj.entry_author.slaves.all()} or None
TypeError: unhashable type: 'dict'
ERROR || 2020-06-23 17:23:37,226 || basehttp || "GET /archives/tvseries/5/ HTTP/1.1" 500 165982
WARNING || 2020-06-23 17:45:05,434 || log || Forbidden: /archives/tvseries/124/delete-image/704,705/
WARNING || 2020-06-23 17:45:05,467 || log || Forbidden: /archives/tvseries/124/delete-image/708,709/
WARNING || 2020-06-23 17:45:05,486 || log || Bad Request: /archives/tvseries/124/delete-image/1000,999/
WARNING || 2020-06-23 17:45:05,555 || log || Bad Request: /archives/tvseries/126/upload-image/small_image.gif/
WARNING || 2020-06-23 17:47:19,932 || log || Forbidden: /archives/tvseries/5/
WARNING || 2020-06-23 17:47:19,933 || basehttp || "GET /archives/tvseries/5/ HTTP/1.1" 403 59
WARNING || 2020-06-23 17:48:14,730 || log || Bad Request: /archives/tvseries/5/
WARNING || 2020-06-23 17:48:14,731 || basehttp || "PUT /archives/tvseries/5/ HTTP/1.1" 400 78
WARNING || 2020-06-23 17:48:43,024 || log || Bad Request: /archives/tvseries/5/
WARNING || 2020-06-23 17:48:43,025 || basehttp || "PUT /archives/tvseries/5/ HTTP/1.1" 400 78
WARNING || 2020-06-23 19:44:17,741 || log || Not Found: /favicon.ico
WARNING || 2020-06-23 19:44:17,741 || basehttp || "GET /favicon.ico HTTP/1.1" 404 12161
WARNING || 2020-06-23 19:50:28,766 || log || Forbidden: /archives/tvseries/5/
WARNING || 2020-06-23 19:50:28,768 || basehttp || "GET /archives/tvseries/5/ HTTP/1.1" 403 14267
WARNING || 2020-06-23 19:52:38,321 || log || Forbidden: /archives/tvseries/34/
WARNING || 2020-06-23 19:53:02,801 || log || Forbidden: /archives/tvseries/36/
WARNING || 2020-06-23 19:59:44,095 || log || Forbidden: /archives/tvseries/5/
WARNING || 2020-06-23 19:59:44,096 || basehttp || "GET /archives/tvseries/5/ HTTP/1.1" 403 14267
ERROR || 2020-06-24 09:52:43,822 || log || Internal Server Error: /archives/tvseries/129/upload-image/new.jpg/
Traceback (most recent call last):
  File "C:\Users\hardcase1\.virtualenvs\series-EAOB5IHD\lib\site-packages\django\core\handlers\exception.py", line 34, in inner
    response = get_response(request)
  File "C:\Users\hardcase1\.virtualenvs\series-EAOB5IHD\lib\site-packages\django\core\handlers\base.py", line 115, in _get_response
    response = self.process_exception_by_middleware(e, request)
  File "C:\Users\hardcase1\.virtualenvs\series-EAOB5IHD\lib\site-packages\django\core\handlers\base.py", line 113, in _get_response
    response = wrapped_callback(request, *callback_args, **callback_kwargs)
  File "C:\Users\hardcase1\.virtualenvs\series-EAOB5IHD\lib\site-packages\django\views\decorators\csrf.py", line 54, in wrapped_view
    return view_func(*args, **kwargs)
  File "C:\Users\hardcase1\.virtualenvs\series-EAOB5IHD\lib\site-packages\django\views\generic\base.py", line 71, in view
    return self.dispatch(request, *args, **kwargs)
  File "C:\Users\hardcase1\.virtualenvs\series-EAOB5IHD\lib\site-packages\rest_framework\views.py", line 505, in dispatch
    response = self.handle_exception(exc)
  File "C:\Users\hardcase1\.virtualenvs\series-EAOB5IHD\lib\site-packages\rest_framework\views.py", line 465, in handle_exception
    self.raise_uncaught_exception(exc)
  File "C:\Users\hardcase1\.virtualenvs\series-EAOB5IHD\lib\site-packages\rest_framework\views.py", line 476, in raise_uncaught_exception
    raise exc
  File "C:\Users\hardcase1\.virtualenvs\series-EAOB5IHD\lib\site-packages\rest_framework\views.py", line 502, in dispatch
    response = handler(request, *args, **kwargs)
  File "C:\Users\hardcase1\.virtualenvs\series-EAOB5IHD\lib\site-packages\rest_framework\generics.py", line 190, in post
    return self.create(request, *args, **kwargs)
  File "C:\Users\hardcase1\PycharmProjects\series\archives\views.py", line 136, in create
    return super().create(request, *args, **kwargs)
  File "C:\Users\hardcase1\.virtualenvs\series-EAOB5IHD\lib\site-packages\rest_framework\mixins.py", line 19, in create
    self.perform_create(serializer)
  File "C:\Users\hardcase1\.virtualenvs\series-EAOB5IHD\lib\site-packages\rest_framework\mixins.py", line 24, in perform_create
    serializer.save()
  File "C:\Users\hardcase1\.virtualenvs\series-EAOB5IHD\lib\site-packages\rest_framework\serializers.py", line 212, in save
    self.instance = self.create(validated_data)
  File "C:\Users\hardcase1\PycharmProjects\series\archives\serializers.py", line 46, in create
    return super().create(validated_data)
  File "C:\Users\hardcase1\.virtualenvs\series-EAOB5IHD\lib\site-packages\rest_framework\serializers.py", line 948, in create
    instance = ModelClass._default_manager.create(**validated_data)
  File "C:\Users\hardcase1\.virtualenvs\series-EAOB5IHD\lib\site-packages\django\db\models\manager.py", line 82, in manager_method
    return getattr(self.get_queryset(), name)(*args, **kwargs)
  File "C:\Users\hardcase1\PycharmProjects\series\archives\managers.py", line 67, in create
    obj.save(force_insert=True, using=self.db, fc=fc)
  File "C:\Users\hardcase1\PycharmProjects\series\archives\models.py", line 393, in save
    self.full_clean(exclude=('image_hash',))
  File "C:\Users\hardcase1\.virtualenvs\series-EAOB5IHD\lib\site-packages\django\db\models\base.py", line 1207, in full_clean
    self.clean()
  File "C:\Users\hardcase1\PycharmProjects\series\archives\models.py", line 368, in clean
    if self.image_hash is None or (self.pk in self.__class__.stored_image_hash.keys()):
AttributeError: 'NoneType' object has no attribute 'keys'
ERROR || 2020-06-24 09:52:43,829 || basehttp || "POST /archives/tvseries/129/upload-image/new.jpg/ HTTP/1.1" 500 27928
ERROR || 2020-06-24 09:54:35,416 || log || Internal Server Error: /archives/tvseries/129/upload-image/new.jpg/
Traceback (most recent call last):
  File "C:\Users\hardcase1\.virtualenvs\series-EAOB5IHD\lib\site-packages\django\core\handlers\exception.py", line 34, in inner
    response = get_response(request)
  File "C:\Users\hardcase1\.virtualenvs\series-EAOB5IHD\lib\site-packages\django\core\handlers\base.py", line 115, in _get_response
    response = self.process_exception_by_middleware(e, request)
  File "C:\Users\hardcase1\.virtualenvs\series-EAOB5IHD\lib\site-packages\django\core\handlers\base.py", line 113, in _get_response
    response = wrapped_callback(request, *callback_args, **callback_kwargs)
  File "C:\Users\hardcase1\.virtualenvs\series-EAOB5IHD\lib\site-packages\django\views\decorators\csrf.py", line 54, in wrapped_view
    return view_func(*args, **kwargs)
  File "C:\Users\hardcase1\.virtualenvs\series-EAOB5IHD\lib\site-packages\django\views\generic\base.py", line 71, in view
    return self.dispatch(request, *args, **kwargs)
  File "C:\Users\hardcase1\.virtualenvs\series-EAOB5IHD\lib\site-packages\rest_framework\views.py", line 505, in dispatch
    response = self.handle_exception(exc)
  File "C:\Users\hardcase1\.virtualenvs\series-EAOB5IHD\lib\site-packages\rest_framework\views.py", line 465, in handle_exception
    self.raise_uncaught_exception(exc)
  File "C:\Users\hardcase1\.virtualenvs\series-EAOB5IHD\lib\site-packages\rest_framework\views.py", line 476, in raise_uncaught_exception
    raise exc
  File "C:\Users\hardcase1\.virtualenvs\series-EAOB5IHD\lib\site-packages\rest_framework\views.py", line 502, in dispatch
    response = handler(request, *args, **kwargs)
  File "C:\Users\hardcase1\.virtualenvs\series-EAOB5IHD\lib\site-packages\rest_framework\generics.py", line 190, in post
    return self.create(request, *args, **kwargs)
  File "C:\Users\hardcase1\PycharmProjects\series\archives\views.py", line 136, in create
    return super().create(request, *args, **kwargs)
  File "C:\Users\hardcase1\.virtualenvs\series-EAOB5IHD\lib\site-packages\rest_framework\mixins.py", line 19, in create
    self.perform_create(serializer)
  File "C:\Users\hardcase1\.virtualenvs\series-EAOB5IHD\lib\site-packages\rest_framework\mixins.py", line 24, in perform_create
    serializer.save()
  File "C:\Users\hardcase1\.virtualenvs\series-EAOB5IHD\lib\site-packages\rest_framework\serializers.py", line 212, in save
    self.instance = self.create(validated_data)
  File "C:\Users\hardcase1\PycharmProjects\series\archives\serializers.py", line 46, in create
    return super().create(validated_data)
  File "C:\Users\hardcase1\.virtualenvs\series-EAOB5IHD\lib\site-packages\rest_framework\serializers.py", line 948, in create
    instance = ModelClass._default_manager.create(**validated_data)
  File "C:\Users\hardcase1\.virtualenvs\series-EAOB5IHD\lib\site-packages\django\db\models\manager.py", line 82, in manager_method
    return getattr(self.get_queryset(), name)(*args, **kwargs)
  File "C:\Users\hardcase1\PycharmProjects\series\archives\managers.py", line 67, in create
    obj.save(force_insert=True, using=self.db, fc=fc)
  File "C:\Users\hardcase1\PycharmProjects\series\archives\models.py", line 393, in save
    self.full_clean(exclude=('image_hash',))
  File "C:\Users\hardcase1\.virtualenvs\series-EAOB5IHD\lib\site-packages\django\db\models\base.py", line 1207, in full_clean
    self.clean()
  File "C:\Users\hardcase1\PycharmProjects\series\archives\models.py", line 372, in clean
    for img_hash in self.__class__.stored_image_hash.values():
AttributeError: 'NoneType' object has no attribute 'values'
ERROR || 2020-06-24 09:54:35,419 || basehttp || "POST /archives/tvseries/129/upload-image/new.jpg/ HTTP/1.1" 500 27907
WARNING || 2020-06-24 09:56:15,168 || log || Bad Request: /archives/tvseries/129/upload-image/new.jpg/
WARNING || 2020-06-24 09:56:15,169 || basehttp || "POST /archives/tvseries/129/upload-image/new.jpg/ HTTP/1.1" 400 60
WARNING || 2020-06-24 09:58:41,923 || log || Not Found: /archives/tvseries/129/delete-image/492,493,494,495,496,497,498,499,500,501,502, 503,504,505,506,507,508,509,510,511/
WARNING || 2020-06-24 09:58:41,923 || basehttp || "DELETE /archives/tvseries/129/delete-image/492,493,494,495,496,497,498,499,500,501,502,%20503,504,505,506,507,508,509,510,511/ HTTP/1.1" 404 13389
WARNING || 2020-06-24 09:59:26,636 || log || Not Found: /archives/tvseries/129/delete-image/493, 494/
WARNING || 2020-06-24 09:59:26,637 || basehttp || "DELETE /archives/tvseries/129/delete-image/493,%20494/ HTTP/1.1" 404 13173
WARNING || 2020-06-24 10:00:21,257 || log || Bad Request: /archives/tvseries/129/upload-image/new.jpg/
WARNING || 2020-06-24 10:00:21,258 || basehttp || "POST /archives/tvseries/129/upload-image/new.jpg/ HTTP/1.1" 400 60
WARNING || 2020-06-24 10:00:33,261 || log || Bad Request: /archives/tvseries/129/upload-image/new.jpg/
WARNING || 2020-06-24 10:00:33,261 || basehttp || "POST /archives/tvseries/129/upload-image/new.jpg/ HTTP/1.1" 400 60
WARNING || 2020-06-24 10:00:38,668 || log || Bad Request: /archives/tvseries/129/upload-image/new.jpg/
WARNING || 2020-06-24 10:00:38,669 || basehttp || "POST /archives/tvseries/129/upload-image/new.jpg/ HTTP/1.1" 400 60
WARNING || 2020-06-24 10:01:12,357 || log || Forbidden: /archives/tvseries/54/delete-image/747,748/
WARNING || 2020-06-24 10:01:12,385 || log || Forbidden: /archives/tvseries/54/delete-image/751,752/
WARNING || 2020-06-24 10:01:12,402 || log || Bad Request: /archives/tvseries/54/delete-image/1000,999/
WARNING || 2020-06-24 10:01:12,459 || log || Bad Request: /archives/tvseries/56/upload-image/small_image.gif/
WARNING || 2020-06-24 10:01:12,649 || log || Forbidden: /archives/tvseries/60/
WARNING || 2020-06-24 10:16:05,612 || log || Forbidden: /archives/tvseries/38/delete-image/790,791/
WARNING || 2020-06-24 10:16:05,627 || log || Forbidden: /archives/tvseries/38/delete-image/794,795/
WARNING || 2020-06-24 10:16:05,643 || log || Bad Request: /archives/tvseries/38/delete-image/1000,999/
WARNING || 2020-06-24 10:16:05,706 || log || Bad Request: /archives/tvseries/40/upload-image/small_image.gif/
WARNING || 2020-06-24 10:16:05,877 || log || Forbidden: /archives/tvseries/44/
WARNING || 2020-06-24 10:17:11,443 || log || Forbidden: /archives/tvseries/38/delete-image/833,834/
WARNING || 2020-06-24 10:17:11,481 || log || Forbidden: /archives/tvseries/38/delete-image/837,838/
WARNING || 2020-06-24 10:17:11,510 || log || Bad Request: /archives/tvseries/38/delete-image/1000,999/
WARNING || 2020-06-24 10:17:11,574 || log || Bad Request: /archives/tvseries/40/upload-image/small_image.gif/
WARNING || 2020-06-24 10:17:11,793 || log || Forbidden: /archives/tvseries/44/
WARNING || 2020-06-24 10:17:21,724 || log || Bad Request: /archives/tvseries/129/upload-image/new.jpg/
WARNING || 2020-06-24 10:17:21,725 || basehttp || "POST /archives/tvseries/129/upload-image/new.jpg/ HTTP/1.1" 400 60
WARNING || 2020-06-24 10:17:23,374 || log || Bad Request: /archives/tvseries/129/upload-image/new.jpg/
WARNING || 2020-06-24 10:17:23,374 || basehttp || "POST /archives/tvseries/129/upload-image/new.jpg/ HTTP/1.1" 400 60
WARNING || 2020-06-24 10:17:37,472 || log || Bad Request: /archives/tvseries/129/upload-image/new.jpg/
WARNING || 2020-06-24 10:17:37,473 || basehttp || "POST /archives/tvseries/129/upload-image/new.jpg/ HTTP/1.1" 400 60
ERROR || 2020-06-24 10:17:59,781 || log || Internal Server Error: /archives/tvseries/129/upload-image/new.jpg/
Traceback (most recent call last):
  File "C:\Users\hardcase1\.virtualenvs\series-EAOB5IHD\lib\site-packages\django\core\handlers\exception.py", line 34, in inner
    response = get_response(request)
  File "C:\Users\hardcase1\.virtualenvs\series-EAOB5IHD\lib\site-packages\django\core\handlers\base.py", line 115, in _get_response
    response = self.process_exception_by_middleware(e, request)
  File "C:\Users\hardcase1\.virtualenvs\series-EAOB5IHD\lib\site-packages\django\core\handlers\base.py", line 113, in _get_response
    response = wrapped_callback(request, *callback_args, **callback_kwargs)
  File "C:\Users\hardcase1\.virtualenvs\series-EAOB5IHD\lib\site-packages\django\views\decorators\csrf.py", line 54, in wrapped_view
    return view_func(*args, **kwargs)
  File "C:\Users\hardcase1\.virtualenvs\series-EAOB5IHD\lib\site-packages\django\views\generic\base.py", line 71, in view
    return self.dispatch(request, *args, **kwargs)
  File "C:\Users\hardcase1\.virtualenvs\series-EAOB5IHD\lib\site-packages\rest_framework\views.py", line 505, in dispatch
    response = self.handle_exception(exc)
  File "C:\Users\hardcase1\.virtualenvs\series-EAOB5IHD\lib\site-packages\rest_framework\views.py", line 465, in handle_exception
    self.raise_uncaught_exception(exc)
  File "C:\Users\hardcase1\.virtualenvs\series-EAOB5IHD\lib\site-packages\rest_framework\views.py", line 476, in raise_uncaught_exception
    raise exc
  File "C:\Users\hardcase1\.virtualenvs\series-EAOB5IHD\lib\site-packages\rest_framework\views.py", line 502, in dispatch
    response = handler(request, *args, **kwargs)
  File "C:\Users\hardcase1\.virtualenvs\series-EAOB5IHD\lib\site-packages\rest_framework\generics.py", line 190, in post
    return self.create(request, *args, **kwargs)
  File "C:\Users\hardcase1\PycharmProjects\series\archives\views.py", line 136, in create
    return super().create(request, *args, **kwargs)
  File "C:\Users\hardcase1\.virtualenvs\series-EAOB5IHD\lib\site-packages\rest_framework\mixins.py", line 19, in create
    self.perform_create(serializer)
  File "C:\Users\hardcase1\.virtualenvs\series-EAOB5IHD\lib\site-packages\rest_framework\mixins.py", line 24, in perform_create
    serializer.save()
  File "C:\Users\hardcase1\.virtualenvs\series-EAOB5IHD\lib\site-packages\rest_framework\serializers.py", line 212, in save
    self.instance = self.create(validated_data)
  File "C:\Users\hardcase1\PycharmProjects\series\archives\serializers.py", line 46, in create
    return super().create(validated_data)
  File "C:\Users\hardcase1\.virtualenvs\series-EAOB5IHD\lib\site-packages\rest_framework\serializers.py", line 948, in create
    instance = ModelClass._default_manager.create(**validated_data)
  File "C:\Users\hardcase1\.virtualenvs\series-EAOB5IHD\lib\site-packages\django\db\models\manager.py", line 82, in manager_method
    return getattr(self.get_queryset(), name)(*args, **kwargs)
  File "C:\Users\hardcase1\PycharmProjects\series\archives\managers.py", line 67, in create
    obj.save(force_insert=True, using=self.db, fc=fc)
  File "C:\Users\hardcase1\PycharmProjects\series\archives\models.py", line 398, in save
    self.full_clean(exclude=('image_hash',))
  File "C:\Users\hardcase1\.virtualenvs\series-EAOB5IHD\lib\site-packages\django\db\models\base.py", line 1207, in full_clean
    self.clean()
  File "C:\Users\hardcase1\PycharmProjects\series\archives\models.py", line 373, in clean
    if self.image_hash is None or (self.pk in self.__class__.stored_image_hash.keys()):
  File "C:\Users\hardcase1\PycharmProjects\series\archives\models.py", line 322, in __getattr__
    return cls.stored_image_hash
  File "C:\Users\hardcase1\PycharmProjects\series\archives\models.py", line 322, in __getattr__
    return cls.stored_image_hash
  File "C:\Users\hardcase1\PycharmProjects\series\archives\models.py", line 322, in __getattr__
    return cls.stored_image_hash
  [Previous line repeated 922 more times]
  File "C:\Users\hardcase1\PycharmProjects\series\archives\models.py", line 320, in __getattr__
    if attrname == 'stored_image_hash':
RecursionError: maximum recursion depth exceeded in comparison
ERROR || 2020-06-24 10:17:59,789 || basehttp || "POST /archives/tvseries/129/upload-image/new.jpg/ HTTP/1.1" 500 147399
WARNING || 2020-06-24 10:18:26,847 || log || Bad Request: /archives/tvseries/129/upload-image/new.jpg/
WARNING || 2020-06-24 10:18:26,848 || basehttp || "POST /archives/tvseries/129/upload-image/new.jpg/ HTTP/1.1" 400 60
WARNING || 2020-06-24 10:20:06,630 || log || Bad Request: /archives/tvseries/129/upload-image/new.jpg/
WARNING || 2020-06-24 10:20:06,631 || basehttp || "POST /archives/tvseries/129/upload-image/new.jpg/ HTTP/1.1" 400 60
WARNING || 2020-06-24 10:20:14,827 || log || Forbidden: /archives/tvseries/38/delete-image/876,877/
WARNING || 2020-06-24 10:20:14,860 || log || Forbidden: /archives/tvseries/38/delete-image/880,881/
WARNING || 2020-06-24 10:20:14,882 || log || Bad Request: /archives/tvseries/38/delete-image/1000,999/
WARNING || 2020-06-24 10:20:14,958 || log || Bad Request: /archives/tvseries/40/upload-image/small_image.gif/
WARNING || 2020-06-24 10:20:15,182 || log || Forbidden: /archives/tvseries/44/
WARNING || 2020-06-24 12:04:55,601 || log || Forbidden: /archives/tvseries/38/delete-image/919,920/
WARNING || 2020-06-24 12:04:55,632 || log || Forbidden: /archives/tvseries/38/delete-image/923,924/
WARNING || 2020-06-24 12:04:55,648 || log || Bad Request: /archives/tvseries/38/delete-image/1000,999/
WARNING || 2020-06-24 12:04:55,726 || log || Bad Request: /archives/tvseries/40/upload-image/small_image.gif/
WARNING || 2020-06-24 12:04:55,929 || log || Forbidden: /archives/tvseries/44/
WARNING || 2020-06-24 12:05:05,232 || log || Bad Request: /archives/tvseries/129/upload-image/new.jpg/
WARNING || 2020-06-24 12:05:05,233 || basehttp || "POST /archives/tvseries/129/upload-image/new.jpg/ HTTP/1.1" 400 60
ERROR || 2020-06-24 12:08:05,423 || log || Internal Server Error: /archives/tvseries/129/delete-image/513/
Traceback (most recent call last):
  File "C:\Users\hardcase1\.virtualenvs\series-EAOB5IHD\lib\site-packages\django\core\handlers\exception.py", line 34, in inner
    response = get_response(request)
  File "C:\Users\hardcase1\.virtualenvs\series-EAOB5IHD\lib\site-packages\django\core\handlers\base.py", line 115, in _get_response
    response = self.process_exception_by_middleware(e, request)
  File "C:\Users\hardcase1\.virtualenvs\series-EAOB5IHD\lib\site-packages\django\core\handlers\base.py", line 113, in _get_response
    response = wrapped_callback(request, *callback_args, **callback_kwargs)
  File "C:\Users\hardcase1\.virtualenvs\series-EAOB5IHD\lib\site-packages\django\views\decorators\csrf.py", line 54, in wrapped_view
    return view_func(*args, **kwargs)
  File "C:\Users\hardcase1\.virtualenvs\series-EAOB5IHD\lib\site-packages\django\views\generic\base.py", line 71, in view
    return self.dispatch(request, *args, **kwargs)
  File "C:\Users\hardcase1\.virtualenvs\series-EAOB5IHD\lib\site-packages\rest_framework\views.py", line 505, in dispatch
    response = self.handle_exception(exc)
  File "C:\Users\hardcase1\.virtualenvs\series-EAOB5IHD\lib\site-packages\rest_framework\views.py", line 465, in handle_exception
    self.raise_uncaught_exception(exc)
  File "C:\Users\hardcase1\.virtualenvs\series-EAOB5IHD\lib\site-packages\rest_framework\views.py", line 476, in raise_uncaught_exception
    raise exc
  File "C:\Users\hardcase1\.virtualenvs\series-EAOB5IHD\lib\site-packages\rest_framework\views.py", line 502, in dispatch
    response = handler(request, *args, **kwargs)
  File "C:\Users\hardcase1\PycharmProjects\series\archives\views.py", line 149, in delete
    self.model.delete_stored_image_hash()
TypeError: delete_stored_image_hash() missing 1 required positional argument: 'self'
ERROR || 2020-06-24 12:08:05,426 || basehttp || "DELETE /archives/tvseries/129/delete-image/513/ HTTP/1.1" 500 26181
WARNING || 2020-06-24 12:08:50,922 || log || Bad Request: /archives/tvseries/129/delete-image/513/
WARNING || 2020-06-24 12:08:50,922 || basehttp || "DELETE /archives/tvseries/129/delete-image/513/ HTTP/1.1" 400 54
WARNING || 2020-06-24 12:09:49,432 || log || Bad Request: /archives/tvseries/129/upload-image/new.jpg/
WARNING || 2020-06-24 12:09:49,432 || basehttp || "POST /archives/tvseries/129/upload-image/new.jpg/ HTTP/1.1" 400 60
WARNING || 2020-06-24 12:13:07,244 || log || Bad Request: /archives/tvseries/129/delete-image/514/
WARNING || 2020-06-24 12:13:07,245 || basehttp || "DELETE /archives/tvseries/129/delete-image/514/ HTTP/1.1" 400 54
ERROR || 2020-06-24 12:13:12,753 || log || Internal Server Error: /archives/tvseries/129/delete-image/515/
Traceback (most recent call last):
  File "C:\Users\hardcase1\.virtualenvs\series-EAOB5IHD\lib\site-packages\django\core\handlers\exception.py", line 34, in inner
    response = get_response(request)
  File "C:\Users\hardcase1\.virtualenvs\series-EAOB5IHD\lib\site-packages\django\core\handlers\base.py", line 115, in _get_response
    response = self.process_exception_by_middleware(e, request)
  File "C:\Users\hardcase1\.virtualenvs\series-EAOB5IHD\lib\site-packages\django\core\handlers\base.py", line 113, in _get_response
    response = wrapped_callback(request, *callback_args, **callback_kwargs)
  File "C:\Users\hardcase1\.virtualenvs\series-EAOB5IHD\lib\site-packages\django\views\decorators\csrf.py", line 54, in wrapped_view
    return view_func(*args, **kwargs)
  File "C:\Users\hardcase1\.virtualenvs\series-EAOB5IHD\lib\site-packages\django\views\generic\base.py", line 71, in view
    return self.dispatch(request, *args, **kwargs)
  File "C:\Users\hardcase1\.virtualenvs\series-EAOB5IHD\lib\site-packages\rest_framework\views.py", line 505, in dispatch
    response = self.handle_exception(exc)
  File "C:\Users\hardcase1\.virtualenvs\series-EAOB5IHD\lib\site-packages\rest_framework\views.py", line 465, in handle_exception
    self.raise_uncaught_exception(exc)
  File "C:\Users\hardcase1\.virtualenvs\series-EAOB5IHD\lib\site-packages\rest_framework\views.py", line 476, in raise_uncaught_exception
    raise exc
  File "C:\Users\hardcase1\.virtualenvs\series-EAOB5IHD\lib\site-packages\rest_framework\views.py", line 502, in dispatch
    response = handler(request, *args, **kwargs)
  File "C:\Users\hardcase1\PycharmProjects\series\archives\views.py", line 149, in delete
    self.model.delete_stored_image_hash(pk)
TypeError: delete_stored_image_hash() missing 1 required positional argument: 'pk'
ERROR || 2020-06-24 12:13:12,754 || basehttp || "DELETE /archives/tvseries/129/delete-image/515/ HTTP/1.1" 500 26179
WARNING || 2020-06-24 12:16:06,281 || log || Bad Request: /archives/tvseries/129/delete-image/515/
WARNING || 2020-06-24 12:16:06,282 || basehttp || "DELETE /archives/tvseries/129/delete-image/515/ HTTP/1.1" 400 54
WARNING || 2020-06-24 12:16:23,866 || log || Bad Request: /archives/tvseries/129/upload-image/new.jpg/
WARNING || 2020-06-24 12:16:23,866 || basehttp || "POST /archives/tvseries/129/upload-image/new.jpg/ HTTP/1.1" 400 60
WARNING || 2020-06-24 12:16:33,590 || log || Bad Request: /archives/tvseries/129/upload-image/new.jpg/
WARNING || 2020-06-24 12:16:33,590 || basehttp || "POST /archives/tvseries/129/upload-image/new.jpg/ HTTP/1.1" 400 60
WARNING || 2020-06-24 12:16:41,942 || log || Forbidden: /archives/tvseries/38/delete-image/962,963/
WARNING || 2020-06-24 12:16:41,973 || log || Forbidden: /archives/tvseries/38/delete-image/966,967/
WARNING || 2020-06-24 12:16:41,989 || log || Bad Request: /archives/tvseries/38/delete-image/1000,999/
WARNING || 2020-06-24 12:16:42,145 || log || Bad Request: /archives/tvseries/40/upload-image/small_image.gif/
WARNING || 2020-06-24 12:16:42,493 || log || Forbidden: /archives/tvseries/44/
ERROR || 2020-06-24 12:16:44,258 || log || Internal Server Error: /archives/tvseries/60/delete-image/978,979/
Traceback (most recent call last):
  File "C:\Users\hardcase1\.virtualenvs\series-EAOB5IHD\lib\site-packages\django\core\handlers\exception.py", line 34, in inner
    response = get_response(request)
  File "C:\Users\hardcase1\.virtualenvs\series-EAOB5IHD\lib\site-packages\django\core\handlers\base.py", line 115, in _get_response
    response = self.process_exception_by_middleware(e, request)
  File "C:\Users\hardcase1\.virtualenvs\series-EAOB5IHD\lib\site-packages\django\core\handlers\base.py", line 113, in _get_response
    response = wrapped_callback(request, *callback_args, **callback_kwargs)
  File "C:\Users\hardcase1\.virtualenvs\series-EAOB5IHD\lib\site-packages\django\views\decorators\csrf.py", line 54, in wrapped_view
    return view_func(*args, **kwargs)
  File "C:\Users\hardcase1\.virtualenvs\series-EAOB5IHD\lib\site-packages\django\views\generic\base.py", line 71, in view
    return self.dispatch(request, *args, **kwargs)
  File "C:\Users\hardcase1\.virtualenvs\series-EAOB5IHD\lib\site-packages\rest_framework\views.py", line 505, in dispatch
    response = self.handle_exception(exc)
  File "C:\Users\hardcase1\.virtualenvs\series-EAOB5IHD\lib\site-packages\rest_framework\views.py", line 465, in handle_exception
    self.raise_uncaught_exception(exc)
  File "C:\Users\hardcase1\.virtualenvs\series-EAOB5IHD\lib\site-packages\rest_framework\views.py", line 476, in raise_uncaught_exception
    raise exc
  File "C:\Users\hardcase1\.virtualenvs\series-EAOB5IHD\lib\site-packages\rest_framework\views.py", line 502, in dispatch
    response = handler(request, *args, **kwargs)
  File "C:\Users\hardcase1\PycharmProjects\series\archives\views.py", line 149, in delete
    self.model.delete_stored_image_hash(pk)
  File "C:\Users\hardcase1\PycharmProjects\series\archives\models.py", line 413, in delete_stored_image_hash
    del cls.stored_image_hash[pk]
KeyError: 978
ERROR || 2020-06-24 12:16:44,308 || log || Internal Server Error: /archives/tvseries/60/delete-image/982,983/
Traceback (most recent call last):
  File "C:\Users\hardcase1\.virtualenvs\series-EAOB5IHD\lib\site-packages\django\core\handlers\exception.py", line 34, in inner
    response = get_response(request)
  File "C:\Users\hardcase1\.virtualenvs\series-EAOB5IHD\lib\site-packages\django\core\handlers\base.py", line 115, in _get_response
    response = self.process_exception_by_middleware(e, request)
  File "C:\Users\hardcase1\.virtualenvs\series-EAOB5IHD\lib\site-packages\django\core\handlers\base.py", line 113, in _get_response
    response = wrapped_callback(request, *callback_args, **callback_kwargs)
  File "C:\Users\hardcase1\.virtualenvs\series-EAOB5IHD\lib\site-packages\django\views\decorators\csrf.py", line 54, in wrapped_view
    return view_func(*args, **kwargs)
  File "C:\Users\hardcase1\.virtualenvs\series-EAOB5IHD\lib\site-packages\django\views\generic\base.py", line 71, in view
    return self.dispatch(request, *args, **kwargs)
  File "C:\Users\hardcase1\.virtualenvs\series-EAOB5IHD\lib\site-packages\rest_framework\views.py", line 505, in dispatch
    response = self.handle_exception(exc)
  File "C:\Users\hardcase1\.virtualenvs\series-EAOB5IHD\lib\site-packages\rest_framework\views.py", line 465, in handle_exception
    self.raise_uncaught_exception(exc)
  File "C:\Users\hardcase1\.virtualenvs\series-EAOB5IHD\lib\site-packages\rest_framework\views.py", line 476, in raise_uncaught_exception
    raise exc
  File "C:\Users\hardcase1\.virtualenvs\series-EAOB5IHD\lib\site-packages\rest_framework\views.py", line 502, in dispatch
    response = handler(request, *args, **kwargs)
  File "C:\Users\hardcase1\PycharmProjects\series\archives\views.py", line 149, in delete
    self.model.delete_stored_image_hash(pk)
  File "C:\Users\hardcase1\PycharmProjects\series\archives\models.py", line 413, in delete_stored_image_hash
    del cls.stored_image_hash[pk]
KeyError: 982
ERROR || 2020-06-24 12:16:44,328 || log || Internal Server Error: /archives/tvseries/60/delete-image/986,987/
Traceback (most recent call last):
  File "C:\Users\hardcase1\.virtualenvs\series-EAOB5IHD\lib\site-packages\django\core\handlers\exception.py", line 34, in inner
    response = get_response(request)
  File "C:\Users\hardcase1\.virtualenvs\series-EAOB5IHD\lib\site-packages\django\core\handlers\base.py", line 115, in _get_response
    response = self.process_exception_by_middleware(e, request)
  File "C:\Users\hardcase1\.virtualenvs\series-EAOB5IHD\lib\site-packages\django\core\handlers\base.py", line 113, in _get_response
    response = wrapped_callback(request, *callback_args, **callback_kwargs)
  File "C:\Users\hardcase1\.virtualenvs\series-EAOB5IHD\lib\site-packages\django\views\decorators\csrf.py", line 54, in wrapped_view
    return view_func(*args, **kwargs)
  File "C:\Users\hardcase1\.virtualenvs\series-EAOB5IHD\lib\site-packages\django\views\generic\base.py", line 71, in view
    return self.dispatch(request, *args, **kwargs)
  File "C:\Users\hardcase1\.virtualenvs\series-EAOB5IHD\lib\site-packages\rest_framework\views.py", line 505, in dispatch
    response = self.handle_exception(exc)
  File "C:\Users\hardcase1\.virtualenvs\series-EAOB5IHD\lib\site-packages\rest_framework\views.py", line 465, in handle_exception
    self.raise_uncaught_exception(exc)
  File "C:\Users\hardcase1\.virtualenvs\series-EAOB5IHD\lib\site-packages\rest_framework\views.py", line 476, in raise_uncaught_exception
    raise exc
  File "C:\Users\hardcase1\.virtualenvs\series-EAOB5IHD\lib\site-packages\rest_framework\views.py", line 502, in dispatch
    response = handler(request, *args, **kwargs)
  File "C:\Users\hardcase1\PycharmProjects\series\archives\views.py", line 149, in delete
    self.model.delete_stored_image_hash(pk)
  File "C:\Users\hardcase1\PycharmProjects\series\archives\models.py", line 413, in delete_stored_image_hash
    del cls.stored_image_hash[pk]
KeyError: 986
ERROR || 2020-06-24 12:16:44,353 || log || Internal Server Error: /archives/tvseries/60/delete-image/990,991/
Traceback (most recent call last):
  File "C:\Users\hardcase1\.virtualenvs\series-EAOB5IHD\lib\site-packages\django\core\handlers\exception.py", line 34, in inner
    response = get_response(request)
  File "C:\Users\hardcase1\.virtualenvs\series-EAOB5IHD\lib\site-packages\django\core\handlers\base.py", line 115, in _get_response
    response = self.process_exception_by_middleware(e, request)
  File "C:\Users\hardcase1\.virtualenvs\series-EAOB5IHD\lib\site-packages\django\core\handlers\base.py", line 113, in _get_response
    response = wrapped_callback(request, *callback_args, **callback_kwargs)
  File "C:\Users\hardcase1\.virtualenvs\series-EAOB5IHD\lib\site-packages\django\views\decorators\csrf.py", line 54, in wrapped_view
    return view_func(*args, **kwargs)
  File "C:\Users\hardcase1\.virtualenvs\series-EAOB5IHD\lib\site-packages\django\views\generic\base.py", line 71, in view
    return self.dispatch(request, *args, **kwargs)
  File "C:\Users\hardcase1\.virtualenvs\series-EAOB5IHD\lib\site-packages\rest_framework\views.py", line 505, in dispatch
    response = self.handle_exception(exc)
  File "C:\Users\hardcase1\.virtualenvs\series-EAOB5IHD\lib\site-packages\rest_framework\views.py", line 465, in handle_exception
    self.raise_uncaught_exception(exc)
  File "C:\Users\hardcase1\.virtualenvs\series-EAOB5IHD\lib\site-packages\rest_framework\views.py", line 476, in raise_uncaught_exception
    raise exc
  File "C:\Users\hardcase1\.virtualenvs\series-EAOB5IHD\lib\site-packages\rest_framework\views.py", line 502, in dispatch
    response = handler(request, *args, **kwargs)
  File "C:\Users\hardcase1\PycharmProjects\series\archives\views.py", line 149, in delete
    self.model.delete_stored_image_hash(pk)
  File "C:\Users\hardcase1\PycharmProjects\series\archives\models.py", line 413, in delete_stored_image_hash
    del cls.stored_image_hash[pk]
KeyError: 990
WARNING || 2020-06-24 12:18:05,422 || log || Forbidden: /archives/tvseries/38/delete-image/1005,1006/
WARNING || 2020-06-24 12:18:05,453 || log || Forbidden: /archives/tvseries/38/delete-image/1009,1010/
WARNING || 2020-06-24 12:18:05,471 || log || Bad Request: /archives/tvseries/38/delete-image/1000,999/
WARNING || 2020-06-24 12:18:05,535 || log || Bad Request: /archives/tvseries/40/upload-image/small_image.gif/
WARNING || 2020-06-24 12:18:05,729 || log || Forbidden: /archives/tvseries/44/
WARNING || 2020-06-24 12:19:18,416 || log || Forbidden: /archives/tvseries/38/delete-image/1048,1049/
WARNING || 2020-06-24 12:19:18,449 || log || Forbidden: /archives/tvseries/38/delete-image/1052,1053/
WARNING || 2020-06-24 12:19:18,466 || log || Bad Request: /archives/tvseries/38/delete-image/1000,999/
WARNING || 2020-06-24 12:19:18,527 || log || Bad Request: /archives/tvseries/40/upload-image/small_image.gif/
WARNING || 2020-06-24 12:19:18,709 || log || Forbidden: /archives/tvseries/44/
WARNING || 2020-06-24 12:19:34,239 || log || Forbidden: /archives/tvseries/38/delete-image/1091,1092/
WARNING || 2020-06-24 12:19:34,255 || log || Forbidden: /archives/tvseries/38/delete-image/1095,1096/
WARNING || 2020-06-24 12:19:34,286 || log || Bad Request: /archives/tvseries/38/delete-image/1000,999/
WARNING || 2020-06-24 12:19:34,468 || log || Bad Request: /archives/tvseries/40/upload-image/small_image.gif/
WARNING || 2020-06-24 12:19:34,653 || log || Forbidden: /archives/tvseries/44/
WARNING || 2020-06-24 12:20:51,764 || log || Forbidden: /archives/tvseries/38/delete-image/1134,1135/
WARNING || 2020-06-24 12:20:51,795 || log || Forbidden: /archives/tvseries/38/delete-image/1138,1139/
WARNING || 2020-06-24 12:20:51,811 || log || Bad Request: /archives/tvseries/38/delete-image/1000,999/
WARNING || 2020-06-24 12:20:51,873 || log || Bad Request: /archives/tvseries/40/upload-image/small_image.gif/
WARNING || 2020-06-24 12:20:52,061 || log || Forbidden: /archives/tvseries/44/
ERROR || 2020-06-24 12:20:53,819 || log || Internal Server Error: /archives/tvseries/60/delete-image/1150,1151/
Traceback (most recent call last):
  File "C:\Users\hardcase1\.virtualenvs\series-EAOB5IHD\lib\site-packages\django\core\handlers\exception.py", line 34, in inner
    response = get_response(request)
  File "C:\Users\hardcase1\.virtualenvs\series-EAOB5IHD\lib\site-packages\django\core\handlers\base.py", line 115, in _get_response
    response = self.process_exception_by_middleware(e, request)
  File "C:\Users\hardcase1\.virtualenvs\series-EAOB5IHD\lib\site-packages\django\core\handlers\base.py", line 113, in _get_response
    response = wrapped_callback(request, *callback_args, **callback_kwargs)
  File "C:\Users\hardcase1\.virtualenvs\series-EAOB5IHD\lib\site-packages\django\views\decorators\csrf.py", line 54, in wrapped_view
    return view_func(*args, **kwargs)
  File "C:\Users\hardcase1\.virtualenvs\series-EAOB5IHD\lib\site-packages\django\views\generic\base.py", line 71, in view
    return self.dispatch(request, *args, **kwargs)
  File "C:\Users\hardcase1\.virtualenvs\series-EAOB5IHD\lib\site-packages\rest_framework\views.py", line 505, in dispatch
    response = self.handle_exception(exc)
  File "C:\Users\hardcase1\.virtualenvs\series-EAOB5IHD\lib\site-packages\rest_framework\views.py", line 465, in handle_exception
    self.raise_uncaught_exception(exc)
  File "C:\Users\hardcase1\.virtualenvs\series-EAOB5IHD\lib\site-packages\rest_framework\views.py", line 476, in raise_uncaught_exception
    raise exc
  File "C:\Users\hardcase1\.virtualenvs\series-EAOB5IHD\lib\site-packages\rest_framework\views.py", line 502, in dispatch
    response = handler(request, *args, **kwargs)
  File "C:\Users\hardcase1\PycharmProjects\series\archives\views.py", line 149, in delete
    self.model.delete_stored_image_hash(pk)
  File "C:\Users\hardcase1\PycharmProjects\series\archives\models.py", line 413, in delete_stored_image_hash
    del cls.stored_image_hash[pk]
KeyError: 1150
ERROR || 2020-06-24 12:20:53,835 || log || Internal Server Error: /archives/tvseries/60/delete-image/1154,1155/
Traceback (most recent call last):
  File "C:\Users\hardcase1\.virtualenvs\series-EAOB5IHD\lib\site-packages\django\core\handlers\exception.py", line 34, in inner
    response = get_response(request)
  File "C:\Users\hardcase1\.virtualenvs\series-EAOB5IHD\lib\site-packages\django\core\handlers\base.py", line 115, in _get_response
    response = self.process_exception_by_middleware(e, request)
  File "C:\Users\hardcase1\.virtualenvs\series-EAOB5IHD\lib\site-packages\django\core\handlers\base.py", line 113, in _get_response
    response = wrapped_callback(request, *callback_args, **callback_kwargs)
  File "C:\Users\hardcase1\.virtualenvs\series-EAOB5IHD\lib\site-packages\django\views\decorators\csrf.py", line 54, in wrapped_view
    return view_func(*args, **kwargs)
  File "C:\Users\hardcase1\.virtualenvs\series-EAOB5IHD\lib\site-packages\django\views\generic\base.py", line 71, in view
    return self.dispatch(request, *args, **kwargs)
  File "C:\Users\hardcase1\.virtualenvs\series-EAOB5IHD\lib\site-packages\rest_framework\views.py", line 505, in dispatch
    response = self.handle_exception(exc)
  File "C:\Users\hardcase1\.virtualenvs\series-EAOB5IHD\lib\site-packages\rest_framework\views.py", line 465, in handle_exception
    self.raise_uncaught_exception(exc)
  File "C:\Users\hardcase1\.virtualenvs\series-EAOB5IHD\lib\site-packages\rest_framework\views.py", line 476, in raise_uncaught_exception
    raise exc
  File "C:\Users\hardcase1\.virtualenvs\series-EAOB5IHD\lib\site-packages\rest_framework\views.py", line 502, in dispatch
    response = handler(request, *args, **kwargs)
  File "C:\Users\hardcase1\PycharmProjects\series\archives\views.py", line 149, in delete
    self.model.delete_stored_image_hash(pk)
  File "C:\Users\hardcase1\PycharmProjects\series\archives\models.py", line 413, in delete_stored_image_hash
    del cls.stored_image_hash[pk]
KeyError: 1154
ERROR || 2020-06-24 12:20:53,851 || log || Internal Server Error: /archives/tvseries/60/delete-image/1158,1159/
Traceback (most recent call last):
  File "C:\Users\hardcase1\.virtualenvs\series-EAOB5IHD\lib\site-packages\django\core\handlers\exception.py", line 34, in inner
    response = get_response(request)
  File "C:\Users\hardcase1\.virtualenvs\series-EAOB5IHD\lib\site-packages\django\core\handlers\base.py", line 115, in _get_response
    response = self.process_exception_by_middleware(e, request)
  File "C:\Users\hardcase1\.virtualenvs\series-EAOB5IHD\lib\site-packages\django\core\handlers\base.py", line 113, in _get_response
    response = wrapped_callback(request, *callback_args, **callback_kwargs)
  File "C:\Users\hardcase1\.virtualenvs\series-EAOB5IHD\lib\site-packages\django\views\decorators\csrf.py", line 54, in wrapped_view
    return view_func(*args, **kwargs)
  File "C:\Users\hardcase1\.virtualenvs\series-EAOB5IHD\lib\site-packages\django\views\generic\base.py", line 71, in view
    return self.dispatch(request, *args, **kwargs)
  File "C:\Users\hardcase1\.virtualenvs\series-EAOB5IHD\lib\site-packages\rest_framework\views.py", line 505, in dispatch
    response = self.handle_exception(exc)
  File "C:\Users\hardcase1\.virtualenvs\series-EAOB5IHD\lib\site-packages\rest_framework\views.py", line 465, in handle_exception
    self.raise_uncaught_exception(exc)
  File "C:\Users\hardcase1\.virtualenvs\series-EAOB5IHD\lib\site-packages\rest_framework\views.py", line 476, in raise_uncaught_exception
    raise exc
  File "C:\Users\hardcase1\.virtualenvs\series-EAOB5IHD\lib\site-packages\rest_framework\views.py", line 502, in dispatch
    response = handler(request, *args, **kwargs)
  File "C:\Users\hardcase1\PycharmProjects\series\archives\views.py", line 149, in delete
    self.model.delete_stored_image_hash(pk)
  File "C:\Users\hardcase1\PycharmProjects\series\archives\models.py", line 413, in delete_stored_image_hash
    del cls.stored_image_hash[pk]
KeyError: 1158
ERROR || 2020-06-24 12:20:53,882 || log || Internal Server Error: /archives/tvseries/60/delete-image/1162,1163/
Traceback (most recent call last):
  File "C:\Users\hardcase1\.virtualenvs\series-EAOB5IHD\lib\site-packages\django\core\handlers\exception.py", line 34, in inner
    response = get_response(request)
  File "C:\Users\hardcase1\.virtualenvs\series-EAOB5IHD\lib\site-packages\django\core\handlers\base.py", line 115, in _get_response
    response = self.process_exception_by_middleware(e, request)
  File "C:\Users\hardcase1\.virtualenvs\series-EAOB5IHD\lib\site-packages\django\core\handlers\base.py", line 113, in _get_response
    response = wrapped_callback(request, *callback_args, **callback_kwargs)
  File "C:\Users\hardcase1\.virtualenvs\series-EAOB5IHD\lib\site-packages\django\views\decorators\csrf.py", line 54, in wrapped_view
    return view_func(*args, **kwargs)
  File "C:\Users\hardcase1\.virtualenvs\series-EAOB5IHD\lib\site-packages\django\views\generic\base.py", line 71, in view
    return self.dispatch(request, *args, **kwargs)
  File "C:\Users\hardcase1\.virtualenvs\series-EAOB5IHD\lib\site-packages\rest_framework\views.py", line 505, in dispatch
    response = self.handle_exception(exc)
  File "C:\Users\hardcase1\.virtualenvs\series-EAOB5IHD\lib\site-packages\rest_framework\views.py", line 465, in handle_exception
    self.raise_uncaught_exception(exc)
  File "C:\Users\hardcase1\.virtualenvs\series-EAOB5IHD\lib\site-packages\rest_framework\views.py", line 476, in raise_uncaught_exception
    raise exc
  File "C:\Users\hardcase1\.virtualenvs\series-EAOB5IHD\lib\site-packages\rest_framework\views.py", line 502, in dispatch
    response = handler(request, *args, **kwargs)
  File "C:\Users\hardcase1\PycharmProjects\series\archives\views.py", line 149, in delete
    self.model.delete_stored_image_hash(pk)
  File "C:\Users\hardcase1\PycharmProjects\series\archives\models.py", line 413, in delete_stored_image_hash
    del cls.stored_image_hash[pk]
KeyError: 1162
WARNING || 2020-06-24 12:22:51,093 || log || Forbidden: /archives/tvseries/38/delete-image/1177,1178/
WARNING || 2020-06-24 12:22:51,108 || log || Forbidden: /archives/tvseries/38/delete-image/1181,1182/
WARNING || 2020-06-24 12:22:51,140 || log || Bad Request: /archives/tvseries/38/delete-image/1000,999/
WARNING || 2020-06-24 12:22:51,202 || log || Bad Request: /archives/tvseries/40/upload-image/small_image.gif/
WARNING || 2020-06-24 12:22:51,506 || log || Forbidden: /archives/tvseries/44/
WARNING || 2020-06-24 12:23:26,037 || log || Forbidden: /archives/tvseries/40/delete-image/1220,1221/
WARNING || 2020-06-24 12:23:26,067 || log || Forbidden: /archives/tvseries/40/delete-image/1224,1225/
WARNING || 2020-06-24 12:23:26,085 || log || Bad Request: /archives/tvseries/40/delete-image/1000,999/
WARNING || 2020-06-24 12:23:26,143 || log || Bad Request: /archives/tvseries/42/upload-image/small_image.gif/
WARNING || 2020-06-24 12:23:26,333 || log || Forbidden: /archives/tvseries/46/
WARNING || 2020-06-24 12:31:15,030 || log || Forbidden: /archives/tvseries/38/delete-image/1263,1264/
WARNING || 2020-06-24 12:31:15,050 || log || Forbidden: /archives/tvseries/38/delete-image/1267,1268/
WARNING || 2020-06-24 12:31:15,066 || log || Bad Request: /archives/tvseries/38/delete-image/1000,999/
WARNING || 2020-06-24 12:31:15,129 || log || Bad Request: /archives/tvseries/40/upload-image/small_image.gif/
WARNING || 2020-06-24 12:31:15,477 || log || Forbidden: /archives/tvseries/44/
WARNING || 2020-06-24 14:07:00,112 || log || Method Not Allowed: /archives/tvseries/5/
WARNING || 2020-06-24 14:07:00,114 || basehttp || "POST /archives/tvseries/5/ HTTP/1.1" 405 42
WARNING || 2020-06-24 14:18:13,726 || log || Bad Request: /archives/tvseries/5/
WARNING || 2020-06-24 14:18:13,727 || basehttp || "PATCH /archives/tvseries/5/ HTTP/1.1" 400 44
WARNING || 2020-06-24 14:21:25,379 || log || Bad Request: /archives/tvseries/5/
WARNING || 2020-06-24 14:21:25,380 || basehttp || "PATCH /archives/tvseries/5/ HTTP/1.1" 400 44
WARNING || 2020-06-24 14:21:27,786 || log || Bad Request: /archives/tvseries/5/
WARNING || 2020-06-24 14:21:27,787 || basehttp || "PATCH /archives/tvseries/5/ HTTP/1.1" 400 44
WARNING || 2020-06-24 14:24:03,860 || log || Bad Request: /archives/tvseries/5/
WARNING || 2020-06-24 14:24:03,861 || basehttp || "PATCH /archives/tvseries/5/ HTTP/1.1" 400 45
WARNING || 2020-06-24 14:28:41,079 || log || Unsupported Media Type: /archives/tvseries/5/
WARNING || 2020-06-24 14:28:41,080 || basehttp || "PATCH /archives/tvseries/5/ HTTP/1.1" 415 63
ERROR || 2020-06-24 14:28:53,688 || log || Internal Server Error: /archives/tvseries/5/
Traceback (most recent call last):
  File "C:\Users\hardcase1\.virtualenvs\series-EAOB5IHD\lib\site-packages\django\core\handlers\exception.py", line 34, in inner
    response = get_response(request)
  File "C:\Users\hardcase1\.virtualenvs\series-EAOB5IHD\lib\site-packages\django\core\handlers\base.py", line 115, in _get_response
    response = self.process_exception_by_middleware(e, request)
  File "C:\Users\hardcase1\.virtualenvs\series-EAOB5IHD\lib\site-packages\django\core\handlers\base.py", line 113, in _get_response
    response = wrapped_callback(request, *callback_args, **callback_kwargs)
  File "C:\Users\hardcase1\.virtualenvs\series-EAOB5IHD\lib\site-packages\django\views\decorators\csrf.py", line 54, in wrapped_view
    return view_func(*args, **kwargs)
  File "C:\Users\hardcase1\.virtualenvs\series-EAOB5IHD\lib\site-packages\django\views\generic\base.py", line 71, in view
    return self.dispatch(request, *args, **kwargs)
  File "C:\Users\hardcase1\.virtualenvs\series-EAOB5IHD\lib\site-packages\rest_framework\views.py", line 505, in dispatch
    response = self.handle_exception(exc)
  File "C:\Users\hardcase1\.virtualenvs\series-EAOB5IHD\lib\site-packages\rest_framework\views.py", line 465, in handle_exception
    self.raise_uncaught_exception(exc)
  File "C:\Users\hardcase1\.virtualenvs\series-EAOB5IHD\lib\site-packages\rest_framework\views.py", line 476, in raise_uncaught_exception
    raise exc
  File "C:\Users\hardcase1\.virtualenvs\series-EAOB5IHD\lib\site-packages\rest_framework\views.py", line 502, in dispatch
    response = handler(request, *args, **kwargs)
  File "C:\Users\hardcase1\.virtualenvs\series-EAOB5IHD\lib\site-packages\rest_framework\generics.py", line 288, in patch
    return self.partial_update(request, *args, **kwargs)
  File "C:\Users\hardcase1\.virtualenvs\series-EAOB5IHD\lib\site-packages\rest_framework\mixins.py", line 82, in partial_update
    return self.update(request, *args, **kwargs)
  File "C:\Users\hardcase1\.virtualenvs\series-EAOB5IHD\lib\site-packages\rest_framework\mixins.py", line 68, in update
    self.perform_update(serializer)
  File "C:\Users\hardcase1\.virtualenvs\series-EAOB5IHD\lib\site-packages\rest_framework\mixins.py", line 78, in perform_update
    serializer.save()
  File "C:\Users\hardcase1\.virtualenvs\series-EAOB5IHD\lib\site-packages\rest_framework\serializers.py", line 207, in save
    self.instance = self.update(self.instance, validated_data)
  File "C:\Users\hardcase1\PycharmProjects\series\archives\serializers.py", line 153, in update
    return super().update(instance, validated_data)
  File "C:\Users\hardcase1\.virtualenvs\series-EAOB5IHD\lib\site-packages\rest_framework\serializers.py", line 978, in update
    raise_errors_on_nested_writes('update', self, validated_data)
  File "C:\Users\hardcase1\.virtualenvs\series-EAOB5IHD\lib\site-packages\rest_framework\serializers.py", line 805, in raise_errors_on_nested_writes
    assert not any(
AssertionError: The `.update()` method does not support writable nested fields by default.
Write an explicit `.update()` method for serializer `archives.serializers.TvSeriesDetailSerializer`, or set `read_only=True` on nested serializer fields.
ERROR || 2020-06-24 14:28:53,690 || basehttp || "PATCH /archives/tvseries/5/ HTTP/1.1" 500 27655
ERROR || 2020-06-24 14:34:25,897 || log || Internal Server Error: /archives/tvseries/5/
Traceback (most recent call last):
  File "C:\Users\hardcase1\.virtualenvs\series-EAOB5IHD\lib\site-packages\django\core\handlers\exception.py", line 34, in inner
    response = get_response(request)
  File "C:\Users\hardcase1\.virtualenvs\series-EAOB5IHD\lib\site-packages\django\core\handlers\base.py", line 115, in _get_response
    response = self.process_exception_by_middleware(e, request)
  File "C:\Users\hardcase1\.virtualenvs\series-EAOB5IHD\lib\site-packages\django\core\handlers\base.py", line 113, in _get_response
    response = wrapped_callback(request, *callback_args, **callback_kwargs)
  File "C:\Users\hardcase1\.virtualenvs\series-EAOB5IHD\lib\site-packages\django\views\decorators\csrf.py", line 54, in wrapped_view
    return view_func(*args, **kwargs)
  File "C:\Users\hardcase1\.virtualenvs\series-EAOB5IHD\lib\site-packages\django\views\generic\base.py", line 71, in view
    return self.dispatch(request, *args, **kwargs)
  File "C:\Users\hardcase1\.virtualenvs\series-EAOB5IHD\lib\site-packages\rest_framework\views.py", line 505, in dispatch
    response = self.handle_exception(exc)
  File "C:\Users\hardcase1\.virtualenvs\series-EAOB5IHD\lib\site-packages\rest_framework\views.py", line 465, in handle_exception
    self.raise_uncaught_exception(exc)
  File "C:\Users\hardcase1\.virtualenvs\series-EAOB5IHD\lib\site-packages\rest_framework\views.py", line 476, in raise_uncaught_exception
    raise exc
  File "C:\Users\hardcase1\.virtualenvs\series-EAOB5IHD\lib\site-packages\rest_framework\views.py", line 502, in dispatch
    response = handler(request, *args, **kwargs)
  File "C:\Users\hardcase1\.virtualenvs\series-EAOB5IHD\lib\site-packages\rest_framework\generics.py", line 288, in patch
    return self.partial_update(request, *args, **kwargs)
  File "C:\Users\hardcase1\.virtualenvs\series-EAOB5IHD\lib\site-packages\rest_framework\mixins.py", line 82, in partial_update
    return self.update(request, *args, **kwargs)
  File "C:\Users\hardcase1\.virtualenvs\series-EAOB5IHD\lib\site-packages\rest_framework\mixins.py", line 68, in update
    self.perform_update(serializer)
  File "C:\Users\hardcase1\.virtualenvs\series-EAOB5IHD\lib\site-packages\rest_framework\mixins.py", line 78, in perform_update
    serializer.save()
  File "C:\Users\hardcase1\.virtualenvs\series-EAOB5IHD\lib\site-packages\rest_framework\serializers.py", line 207, in save
    self.instance = self.update(self.instance, validated_data)
  File "C:\Users\hardcase1\PycharmProjects\series\archives\serializers.py", line 153, in update
    validated_data.pop('interrelationship')
KeyError: 'interrelationship'
ERROR || 2020-06-24 14:34:25,900 || basehttp || "PATCH /archives/tvseries/5/ HTTP/1.1" 500 26856
ERROR || 2020-06-24 15:17:54,914 || log || Internal Server Error: /archives/tvseries/5/
Traceback (most recent call last):
  File "C:\Users\hardcase1\.virtualenvs\series-EAOB5IHD\lib\site-packages\django\core\handlers\exception.py", line 34, in inner
    response = get_response(request)
  File "C:\Users\hardcase1\.virtualenvs\series-EAOB5IHD\lib\site-packages\django\core\handlers\base.py", line 115, in _get_response
    response = self.process_exception_by_middleware(e, request)
  File "C:\Users\hardcase1\.virtualenvs\series-EAOB5IHD\lib\site-packages\django\core\handlers\base.py", line 113, in _get_response
    response = wrapped_callback(request, *callback_args, **callback_kwargs)
  File "C:\Users\hardcase1\.virtualenvs\series-EAOB5IHD\lib\site-packages\django\views\decorators\csrf.py", line 54, in wrapped_view
    return view_func(*args, **kwargs)
  File "C:\Users\hardcase1\.virtualenvs\series-EAOB5IHD\lib\site-packages\django\views\generic\base.py", line 71, in view
    return self.dispatch(request, *args, **kwargs)
  File "C:\Users\hardcase1\.virtualenvs\series-EAOB5IHD\lib\site-packages\rest_framework\views.py", line 505, in dispatch
    response = self.handle_exception(exc)
  File "C:\Users\hardcase1\.virtualenvs\series-EAOB5IHD\lib\site-packages\rest_framework\views.py", line 465, in handle_exception
    self.raise_uncaught_exception(exc)
  File "C:\Users\hardcase1\.virtualenvs\series-EAOB5IHD\lib\site-packages\rest_framework\views.py", line 476, in raise_uncaught_exception
    raise exc
  File "C:\Users\hardcase1\.virtualenvs\series-EAOB5IHD\lib\site-packages\rest_framework\views.py", line 502, in dispatch
    response = handler(request, *args, **kwargs)
  File "C:\Users\hardcase1\.virtualenvs\series-EAOB5IHD\lib\site-packages\rest_framework\generics.py", line 288, in patch
    return self.partial_update(request, *args, **kwargs)
  File "C:\Users\hardcase1\.virtualenvs\series-EAOB5IHD\lib\site-packages\rest_framework\mixins.py", line 82, in partial_update
    return self.update(request, *args, **kwargs)
  File "C:\Users\hardcase1\.virtualenvs\series-EAOB5IHD\lib\site-packages\rest_framework\mixins.py", line 68, in update
    self.perform_update(serializer)
  File "C:\Users\hardcase1\.virtualenvs\series-EAOB5IHD\lib\site-packages\rest_framework\mixins.py", line 78, in perform_update
    serializer.save()
  File "C:\Users\hardcase1\.virtualenvs\series-EAOB5IHD\lib\site-packages\rest_framework\serializers.py", line 207, in save
    self.instance = self.update(self.instance, validated_data)
  File "C:\Users\hardcase1\PycharmProjects\series\archives\serializers.py", line 162, in update
    set_of_interrelationships.add(
  File "C:\Users\hardcase1\.virtualenvs\series-EAOB5IHD\lib\site-packages\django\db\models\base.py", line 535, in __hash__
    raise TypeError("Model instances without primary key value are unhashable")
TypeError: Model instances without primary key value are unhashable
ERROR || 2020-06-24 15:17:54,915 || basehttp || "PATCH /archives/tvseries/5/ HTTP/1.1" 500 27126
WARNING || 2020-06-24 15:39:39,455 || log || Forbidden: /archives/tvseries/38/delete-image/1306,1307/
WARNING || 2020-06-24 15:39:39,482 || log || Forbidden: /archives/tvseries/38/delete-image/1310,1311/
WARNING || 2020-06-24 15:39:39,505 || log || Bad Request: /archives/tvseries/38/delete-image/1000,999/
WARNING || 2020-06-24 15:39:39,563 || log || Bad Request: /archives/tvseries/40/upload-image/small_image.gif/
WARNING || 2020-06-24 15:39:39,767 || log || Forbidden: /archives/tvseries/44/
ERROR || 2020-06-24 15:40:33,051 || log || Internal Server Error: /archives/tvseries/5/
Traceback (most recent call last):
  File "C:\Users\hardcase1\.virtualenvs\series-EAOB5IHD\lib\site-packages\django\core\handlers\exception.py", line 34, in inner
    response = get_response(request)
  File "C:\Users\hardcase1\.virtualenvs\series-EAOB5IHD\lib\site-packages\django\core\handlers\base.py", line 115, in _get_response
    response = self.process_exception_by_middleware(e, request)
  File "C:\Users\hardcase1\.virtualenvs\series-EAOB5IHD\lib\site-packages\django\core\handlers\base.py", line 113, in _get_response
    response = wrapped_callback(request, *callback_args, **callback_kwargs)
  File "C:\Users\hardcase1\.virtualenvs\series-EAOB5IHD\lib\site-packages\django\views\decorators\csrf.py", line 54, in wrapped_view
    return view_func(*args, **kwargs)
  File "C:\Users\hardcase1\.virtualenvs\series-EAOB5IHD\lib\site-packages\django\views\generic\base.py", line 71, in view
    return self.dispatch(request, *args, **kwargs)
  File "C:\Users\hardcase1\.virtualenvs\series-EAOB5IHD\lib\site-packages\rest_framework\views.py", line 505, in dispatch
    response = self.handle_exception(exc)
  File "C:\Users\hardcase1\.virtualenvs\series-EAOB5IHD\lib\site-packages\rest_framework\views.py", line 465, in handle_exception
    self.raise_uncaught_exception(exc)
  File "C:\Users\hardcase1\.virtualenvs\series-EAOB5IHD\lib\site-packages\rest_framework\views.py", line 476, in raise_uncaught_exception
    raise exc
  File "C:\Users\hardcase1\.virtualenvs\series-EAOB5IHD\lib\site-packages\rest_framework\views.py", line 502, in dispatch
    response = handler(request, *args, **kwargs)
  File "C:\Users\hardcase1\.virtualenvs\series-EAOB5IHD\lib\site-packages\rest_framework\generics.py", line 288, in patch
    return self.partial_update(request, *args, **kwargs)
  File "C:\Users\hardcase1\.virtualenvs\series-EAOB5IHD\lib\site-packages\rest_framework\mixins.py", line 82, in partial_update
    return self.update(request, *args, **kwargs)
  File "C:\Users\hardcase1\.virtualenvs\series-EAOB5IHD\lib\site-packages\rest_framework\mixins.py", line 68, in update
    self.perform_update(serializer)
  File "C:\Users\hardcase1\.virtualenvs\series-EAOB5IHD\lib\site-packages\rest_framework\mixins.py", line 78, in perform_update
    serializer.save()
  File "C:\Users\hardcase1\.virtualenvs\series-EAOB5IHD\lib\site-packages\rest_framework\serializers.py", line 207, in save
    self.instance = self.update(self.instance, validated_data)
  File "C:\Users\hardcase1\PycharmProjects\series\archives\serializers.py", line 162, in update
    set_of_interrelationships.add(
TypeError: __hash__ method should return an integer
ERROR || 2020-06-24 15:40:33,052 || basehttp || "PATCH /archives/tvseries/5/ HTTP/1.1" 500 26891
