ERROR || 2020-06-22 15:32:25,227 || log || Internal Server Error: /archives/tvseries/5/
Traceback (most recent call last):
  File "C:\Users\hardcase1\.virtualenvs\series-EAOB5IHD\lib\site-packages\django\core\handlers\exception.py", line 34, in inner
    response = get_response(request)
  File "C:\Users\hardcase1\.virtualenvs\series-EAOB5IHD\lib\site-packages\django\core\handlers\base.py", line 115, in _get_response
    response = self.process_exception_by_middleware(e, request)
  File "C:\Users\hardcase1\.virtualenvs\series-EAOB5IHD\lib\site-packages\django\core\handlers\base.py", line 113, in _get_response
    response = wrapped_callback(request, *callback_args, **callback_kwargs)
  File "C:\Users\hardcase1\.virtualenvs\series-EAOB5IHD\lib\site-packages\django\views\decorators\csrf.py", line 54, in wrapped_view
    return view_func(*args, **kwargs)
  File "C:\Users\hardcase1\.virtualenvs\series-EAOB5IHD\lib\site-packages\django\views\generic\base.py", line 71, in view
    return self.dispatch(request, *args, **kwargs)
  File "C:\Users\hardcase1\.virtualenvs\series-EAOB5IHD\lib\site-packages\rest_framework\views.py", line 505, in dispatch
    response = self.handle_exception(exc)
  File "C:\Users\hardcase1\.virtualenvs\series-EAOB5IHD\lib\site-packages\rest_framework\views.py", line 465, in handle_exception
    self.raise_uncaught_exception(exc)
  File "C:\Users\hardcase1\.virtualenvs\series-EAOB5IHD\lib\site-packages\rest_framework\views.py", line 476, in raise_uncaught_exception
    raise exc
  File "C:\Users\hardcase1\.virtualenvs\series-EAOB5IHD\lib\site-packages\rest_framework\views.py", line 502, in dispatch
    response = handler(request, *args, **kwargs)
  File "C:\Users\hardcase1\.virtualenvs\series-EAOB5IHD\lib\site-packages\rest_framework\generics.py", line 282, in get
    return self.retrieve(request, *args, **kwargs)
  File "C:\Users\hardcase1\.virtualenvs\series-EAOB5IHD\lib\site-packages\rest_framework\mixins.py", line 56, in retrieve
    return Response(serializer.data)
  File "C:\Users\hardcase1\.virtualenvs\series-EAOB5IHD\lib\site-packages\rest_framework\serializers.py", line 562, in data
    ret = super().data
  File "C:\Users\hardcase1\.virtualenvs\series-EAOB5IHD\lib\site-packages\rest_framework\serializers.py", line 260, in data
    self._data = self.to_representation(self.instance)
  File "C:\Users\hardcase1\PycharmProjects\series\series\helpers\serializer_mixins.py", line 104, in to_representation
    data = super().to_representation(instance)
  File "C:\Users\hardcase1\.virtualenvs\series-EAOB5IHD\lib\site-packages\rest_framework\serializers.py", line 529, in to_representation
    ret[field.field_name] = field.to_representation(attribute)
  File "C:\Users\hardcase1\.virtualenvs\series-EAOB5IHD\lib\site-packages\rest_framework\fields.py", line 1905, in to_representation
    return method(value)
  File "C:\Users\hardcase1\PycharmProjects\series\archives\serializers.py", line 144, in get_allowed_redactors
    name=obj.entry_author.master.get_full_name(),
AttributeError: 'NoneType' object has no attribute 'get_full_name'
ERROR || 2020-06-22 15:32:25,389 || basehttp || "GET /archives/tvseries/5/ HTTP/1.1" 500 164741
ERROR || 2020-06-22 15:34:31,391 || log || Internal Server Error: /archives/tvseries/5/
Traceback (most recent call last):
  File "C:\Users\hardcase1\.virtualenvs\series-EAOB5IHD\lib\site-packages\django\core\handlers\exception.py", line 34, in inner
    response = get_response(request)
  File "C:\Users\hardcase1\.virtualenvs\series-EAOB5IHD\lib\site-packages\django\core\handlers\base.py", line 115, in _get_response
    response = self.process_exception_by_middleware(e, request)
  File "C:\Users\hardcase1\.virtualenvs\series-EAOB5IHD\lib\site-packages\django\core\handlers\base.py", line 113, in _get_response
    response = wrapped_callback(request, *callback_args, **callback_kwargs)
  File "C:\Users\hardcase1\.virtualenvs\series-EAOB5IHD\lib\site-packages\django\views\decorators\csrf.py", line 54, in wrapped_view
    return view_func(*args, **kwargs)
  File "C:\Users\hardcase1\.virtualenvs\series-EAOB5IHD\lib\site-packages\django\views\generic\base.py", line 71, in view
    return self.dispatch(request, *args, **kwargs)
  File "C:\Users\hardcase1\.virtualenvs\series-EAOB5IHD\lib\site-packages\rest_framework\views.py", line 505, in dispatch
    response = self.handle_exception(exc)
  File "C:\Users\hardcase1\.virtualenvs\series-EAOB5IHD\lib\site-packages\rest_framework\views.py", line 465, in handle_exception
    self.raise_uncaught_exception(exc)
  File "C:\Users\hardcase1\.virtualenvs\series-EAOB5IHD\lib\site-packages\rest_framework\views.py", line 476, in raise_uncaught_exception
    raise exc
  File "C:\Users\hardcase1\.virtualenvs\series-EAOB5IHD\lib\site-packages\rest_framework\views.py", line 502, in dispatch
    response = handler(request, *args, **kwargs)
  File "C:\Users\hardcase1\.virtualenvs\series-EAOB5IHD\lib\site-packages\rest_framework\generics.py", line 282, in get
    return self.retrieve(request, *args, **kwargs)
  File "C:\Users\hardcase1\.virtualenvs\series-EAOB5IHD\lib\site-packages\rest_framework\mixins.py", line 56, in retrieve
    return Response(serializer.data)
  File "C:\Users\hardcase1\.virtualenvs\series-EAOB5IHD\lib\site-packages\rest_framework\serializers.py", line 562, in data
    ret = super().data
  File "C:\Users\hardcase1\.virtualenvs\series-EAOB5IHD\lib\site-packages\rest_framework\serializers.py", line 260, in data
    self._data = self.to_representation(self.instance)
  File "C:\Users\hardcase1\PycharmProjects\series\series\helpers\serializer_mixins.py", line 104, in to_representation
    data = super().to_representation(instance)
  File "C:\Users\hardcase1\.virtualenvs\series-EAOB5IHD\lib\site-packages\rest_framework\serializers.py", line 529, in to_representation
    ret[field.field_name] = field.to_representation(attribute)
  File "C:\Users\hardcase1\.virtualenvs\series-EAOB5IHD\lib\site-packages\rest_framework\fields.py", line 1905, in to_representation
    return method(value)
  File "C:\Users\hardcase1\PycharmProjects\series\archives\serializers.py", line 137, in get_allowed_redactors
    name=obj.entry_author.master.get_full_name(),
AttributeError: 'NoneType' object has no attribute 'get_full_name'
ERROR || 2020-06-22 15:34:31,558 || basehttp || "GET /archives/tvseries/5/ HTTP/1.1" 500 164871
ERROR || 2020-06-22 15:35:04,010 || log || Internal Server Error: /archives/tvseries/14/
Traceback (most recent call last):
  File "C:\Users\hardcase1\.virtualenvs\series-EAOB5IHD\lib\site-packages\django\core\handlers\exception.py", line 34, in inner
    response = get_response(request)
  File "C:\Users\hardcase1\.virtualenvs\series-EAOB5IHD\lib\site-packages\django\core\handlers\base.py", line 115, in _get_response
    response = self.process_exception_by_middleware(e, request)
  File "C:\Users\hardcase1\.virtualenvs\series-EAOB5IHD\lib\site-packages\django\core\handlers\base.py", line 113, in _get_response
    response = wrapped_callback(request, *callback_args, **callback_kwargs)
  File "C:\Users\hardcase1\.virtualenvs\series-EAOB5IHD\lib\site-packages\django\views\decorators\csrf.py", line 54, in wrapped_view
    return view_func(*args, **kwargs)
  File "C:\Users\hardcase1\.virtualenvs\series-EAOB5IHD\lib\site-packages\django\views\generic\base.py", line 71, in view
    return self.dispatch(request, *args, **kwargs)
  File "C:\Users\hardcase1\.virtualenvs\series-EAOB5IHD\lib\site-packages\rest_framework\views.py", line 505, in dispatch
    response = self.handle_exception(exc)
  File "C:\Users\hardcase1\.virtualenvs\series-EAOB5IHD\lib\site-packages\rest_framework\views.py", line 465, in handle_exception
    self.raise_uncaught_exception(exc)
  File "C:\Users\hardcase1\.virtualenvs\series-EAOB5IHD\lib\site-packages\rest_framework\views.py", line 476, in raise_uncaught_exception
    raise exc
  File "C:\Users\hardcase1\.virtualenvs\series-EAOB5IHD\lib\site-packages\rest_framework\views.py", line 502, in dispatch
    response = handler(request, *args, **kwargs)
  File "C:\Users\hardcase1\.virtualenvs\series-EAOB5IHD\lib\site-packages\rest_framework\generics.py", line 282, in get
    return self.retrieve(request, *args, **kwargs)
  File "C:\Users\hardcase1\.virtualenvs\series-EAOB5IHD\lib\site-packages\rest_framework\mixins.py", line 56, in retrieve
    return Response(serializer.data)
  File "C:\Users\hardcase1\.virtualenvs\series-EAOB5IHD\lib\site-packages\rest_framework\serializers.py", line 562, in data
    ret = super().data
  File "C:\Users\hardcase1\.virtualenvs\series-EAOB5IHD\lib\site-packages\rest_framework\serializers.py", line 260, in data
    self._data = self.to_representation(self.instance)
  File "C:\Users\hardcase1\PycharmProjects\series\series\helpers\serializer_mixins.py", line 104, in to_representation
    data = super().to_representation(instance)
  File "C:\Users\hardcase1\.virtualenvs\series-EAOB5IHD\lib\site-packages\rest_framework\serializers.py", line 529, in to_representation
    ret[field.field_name] = field.to_representation(attribute)
  File "C:\Users\hardcase1\.virtualenvs\series-EAOB5IHD\lib\site-packages\rest_framework\fields.py", line 1905, in to_representation
    return method(value)
  File "C:\Users\hardcase1\PycharmProjects\series\archives\serializers.py", line 137, in get_allowed_redactors
    name=obj.entry_author.master.get_full_name(),
AttributeError: 'NoneType' object has no attribute 'get_full_name'
ERROR || 2020-06-22 15:35:04,134 || basehttp || "GET /archives/tvseries/14/ HTTP/1.1" 500 164584
