ERROR || 2020-08-07 15:39:49,599 || log || Internal Server Error: /user-resources/operations-history/
Traceback (most recent call last):
  File "C:\Users\hardcase1\.virtualenvs\series-EAOB5IHD\lib\site-packages\django\core\handlers\exception.py", line 47, in inner
    response = get_response(request)
  File "C:\Users\hardcase1\.virtualenvs\series-EAOB5IHD\lib\site-packages\django\core\handlers\base.py", line 179, in _get_response
    response = wrapped_callback(request, *callback_args, **callback_kwargs)
  File "C:\Users\hardcase1\.virtualenvs\series-EAOB5IHD\lib\site-packages\django\views\decorators\csrf.py", line 54, in wrapped_view
    return view_func(*args, **kwargs)
  File "C:\Users\hardcase1\.virtualenvs\series-EAOB5IHD\lib\site-packages\django\views\generic\base.py", line 73, in view
    return self.dispatch(request, *args, **kwargs)
  File "C:\Users\hardcase1\.virtualenvs\series-EAOB5IHD\lib\site-packages\rest_framework\views.py", line 505, in dispatch
    response = self.handle_exception(exc)
  File "C:\Users\hardcase1\.virtualenvs\series-EAOB5IHD\lib\site-packages\rest_framework\views.py", line 465, in handle_exception
    self.raise_uncaught_exception(exc)
  File "C:\Users\hardcase1\.virtualenvs\series-EAOB5IHD\lib\site-packages\rest_framework\views.py", line 476, in raise_uncaught_exception
    raise exc
  File "C:\Users\hardcase1\.virtualenvs\series-EAOB5IHD\lib\site-packages\rest_framework\views.py", line 502, in dispatch
    response = handler(request, *args, **kwargs)
  File "C:\Users\hardcase1\.virtualenvs\series-EAOB5IHD\lib\site-packages\rest_framework\generics.py", line 199, in get
    return self.list(request, *args, **kwargs)
  File "C:\Users\hardcase1\.virtualenvs\series-EAOB5IHD\lib\site-packages\rest_framework\mixins.py", line 38, in list
    queryset = self.filter_queryset(self.get_queryset())
  File "C:\Users\hardcase1\PycharmProjects\series\users\views.py", line 277, in get_queryset
    ).only([f.name for f in self.model.local_fields])
AttributeError: type object 'EntriesChangeLog' has no attribute 'local_fields'
ERROR || 2020-08-07 15:39:49,690 || basehttp || "GET /user-resources/operations-history/ HTTP/1.1" 500 125548
ERROR || 2020-08-07 15:40:13,834 || log || Internal Server Error: /user-resources/operations-history/
Traceback (most recent call last):
  File "C:\Users\hardcase1\.virtualenvs\series-EAOB5IHD\lib\site-packages\django\core\handlers\exception.py", line 47, in inner
    response = get_response(request)
  File "C:\Users\hardcase1\.virtualenvs\series-EAOB5IHD\lib\site-packages\django\core\handlers\base.py", line 179, in _get_response
    response = wrapped_callback(request, *callback_args, **callback_kwargs)
  File "C:\Users\hardcase1\.virtualenvs\series-EAOB5IHD\lib\site-packages\django\views\decorators\csrf.py", line 54, in wrapped_view
    return view_func(*args, **kwargs)
  File "C:\Users\hardcase1\.virtualenvs\series-EAOB5IHD\lib\site-packages\django\views\generic\base.py", line 73, in view
    return self.dispatch(request, *args, **kwargs)
  File "C:\Users\hardcase1\.virtualenvs\series-EAOB5IHD\lib\site-packages\rest_framework\views.py", line 505, in dispatch
    response = self.handle_exception(exc)
  File "C:\Users\hardcase1\.virtualenvs\series-EAOB5IHD\lib\site-packages\rest_framework\views.py", line 465, in handle_exception
    self.raise_uncaught_exception(exc)
  File "C:\Users\hardcase1\.virtualenvs\series-EAOB5IHD\lib\site-packages\rest_framework\views.py", line 476, in raise_uncaught_exception
    raise exc
  File "C:\Users\hardcase1\.virtualenvs\series-EAOB5IHD\lib\site-packages\rest_framework\views.py", line 502, in dispatch
    response = handler(request, *args, **kwargs)
  File "C:\Users\hardcase1\.virtualenvs\series-EAOB5IHD\lib\site-packages\rest_framework\generics.py", line 199, in get
    return self.list(request, *args, **kwargs)
  File "C:\Users\hardcase1\.virtualenvs\series-EAOB5IHD\lib\site-packages\rest_framework\mixins.py", line 38, in list
    queryset = self.filter_queryset(self.get_queryset())
  File "C:\Users\hardcase1\PycharmProjects\series\users\views.py", line 269, in get_queryset
    self.queryset = self.model.objects.filter(user=self.request.user). \
  File "C:\Users\hardcase1\.virtualenvs\series-EAOB5IHD\lib\site-packages\django\db\models\query.py", line 1196, in only
    field = field.split(LOOKUP_SEP, 1)[0]
AttributeError: 'list' object has no attribute 'split'
ERROR || 2020-08-07 15:40:13,957 || basehttp || "GET /user-resources/operations-history/ HTTP/1.1" 500 132041
ERROR || 2020-08-07 15:50:49,855 || log || Internal Server Error: /user-resources/operations-history/
Traceback (most recent call last):
  File "C:\Users\hardcase1\.virtualenvs\series-EAOB5IHD\lib\site-packages\rest_framework\fields.py", line 454, in get_attribute
    return get_attribute(instance, self.source_attrs)
  File "C:\Users\hardcase1\.virtualenvs\series-EAOB5IHD\lib\site-packages\rest_framework\fields.py", line 94, in get_attribute
    instance = getattr(instance, attr)
AttributeError: 'str' object has no attribute 'content_type'

During handling of the above exception, another exception occurred:

Traceback (most recent call last):
  File "C:\Users\hardcase1\.virtualenvs\series-EAOB5IHD\lib\site-packages\django\core\handlers\exception.py", line 47, in inner
    response = get_response(request)
  File "C:\Users\hardcase1\.virtualenvs\series-EAOB5IHD\lib\site-packages\django\core\handlers\base.py", line 179, in _get_response
    response = wrapped_callback(request, *callback_args, **callback_kwargs)
  File "C:\Users\hardcase1\.virtualenvs\series-EAOB5IHD\lib\site-packages\django\views\decorators\csrf.py", line 54, in wrapped_view
    return view_func(*args, **kwargs)
  File "C:\Users\hardcase1\.virtualenvs\series-EAOB5IHD\lib\site-packages\django\views\generic\base.py", line 73, in view
    return self.dispatch(request, *args, **kwargs)
  File "C:\Users\hardcase1\.virtualenvs\series-EAOB5IHD\lib\site-packages\rest_framework\views.py", line 505, in dispatch
    response = self.handle_exception(exc)
  File "C:\Users\hardcase1\.virtualenvs\series-EAOB5IHD\lib\site-packages\rest_framework\views.py", line 465, in handle_exception
    self.raise_uncaught_exception(exc)
  File "C:\Users\hardcase1\.virtualenvs\series-EAOB5IHD\lib\site-packages\rest_framework\views.py", line 476, in raise_uncaught_exception
    raise exc
  File "C:\Users\hardcase1\.virtualenvs\series-EAOB5IHD\lib\site-packages\rest_framework\views.py", line 502, in dispatch
    response = handler(request, *args, **kwargs)
  File "C:\Users\hardcase1\.virtualenvs\series-EAOB5IHD\lib\site-packages\rest_framework\generics.py", line 199, in get
    return self.list(request, *args, **kwargs)
  File "C:\Users\hardcase1\.virtualenvs\series-EAOB5IHD\lib\site-packages\rest_framework\mixins.py", line 43, in list
    return self.get_paginated_response(serializer.data)
  File "C:\Users\hardcase1\.virtualenvs\series-EAOB5IHD\lib\site-packages\rest_framework\serializers.py", line 760, in data
    ret = super().data
  File "C:\Users\hardcase1\.virtualenvs\series-EAOB5IHD\lib\site-packages\rest_framework\serializers.py", line 260, in data
    self._data = self.to_representation(self.instance)
  File "C:\Users\hardcase1\.virtualenvs\series-EAOB5IHD\lib\site-packages\rest_framework\serializers.py", line 677, in to_representation
    return [
  File "C:\Users\hardcase1\.virtualenvs\series-EAOB5IHD\lib\site-packages\rest_framework\serializers.py", line 678, in <listcomp>
    self.child.to_representation(item) for item in iterable
  File "C:\Users\hardcase1\.virtualenvs\series-EAOB5IHD\lib\site-packages\rest_framework\serializers.py", line 516, in to_representation
    attribute = field.get_attribute(instance)
  File "C:\Users\hardcase1\.virtualenvs\series-EAOB5IHD\lib\site-packages\rest_framework\fields.py", line 487, in get_attribute
    raise type(exc)(msg)
AttributeError: Got AttributeError when attempting to get a value for field `model` on serializer `UserHistorySerializer`.
The serializer field might be named incorrectly and not match any attribute or key on the `str` instance.
Original exception text was: 'str' object has no attribute 'content_type'.
ERROR || 2020-08-07 15:50:49,976 || basehttp || "GET /user-resources/operations-history/ HTTP/1.1" 500 167079
ERROR || 2020-08-07 17:32:12,451 || log || Internal Server Error: /user-resources/operations-history/
Traceback (most recent call last):
  File "C:\Users\hardcase1\.virtualenvs\series-EAOB5IHD\lib\site-packages\rest_framework\pagination.py", line 510, in get_count
    return queryset.count()
  File "C:\Users\hardcase1\.virtualenvs\series-EAOB5IHD\lib\site-packages\django\db\models\query.py", line 411, in count
    return self.query.get_count(using=self.db)
  File "C:\Users\hardcase1\.virtualenvs\series-EAOB5IHD\lib\site-packages\django\db\models\sql\query.py", line 515, in get_count
    number = obj.get_aggregation(using, ['__count'])['__count']
  File "C:\Users\hardcase1\.virtualenvs\series-EAOB5IHD\lib\site-packages\django\db\models\sql\query.py", line 483, in get_aggregation
    outer_query.add_subquery(inner_query, using)
  File "C:\Users\hardcase1\.virtualenvs\series-EAOB5IHD\lib\site-packages\django\db\models\sql\subqueries.py", line 162, in add_subquery
    self.subquery, self.sub_params = query.get_compiler(using).as_sql(with_col_aliases=True)
  File "C:\Users\hardcase1\.virtualenvs\series-EAOB5IHD\lib\site-packages\django\db\models\sql\compiler.py", line 498, in as_sql
    extra_select, order_by, group_by = self.pre_sql_setup()
  File "C:\Users\hardcase1\.virtualenvs\series-EAOB5IHD\lib\site-packages\django\db\models\sql\compiler.py", line 55, in pre_sql_setup
    self.setup_query()
  File "C:\Users\hardcase1\.virtualenvs\series-EAOB5IHD\lib\site-packages\django\db\models\sql\compiler.py", line 46, in setup_query
    self.select, self.klass_info, self.annotation_col_map = self.get_select()
  File "C:\Users\hardcase1\.virtualenvs\series-EAOB5IHD\lib\site-packages\django\db\models\sql\compiler.py", line 267, in get_select
    sql, params = col.select_format(self, sql, params)
  File "C:\Users\hardcase1\.virtualenvs\series-EAOB5IHD\lib\site-packages\django\db\models\expressions.py", line 387, in select_format
    return self.output_field.select_format(compiler, sql, params)
TypeError: select_format() missing 1 required positional argument: 'params'

During handling of the above exception, another exception occurred:

Traceback (most recent call last):
  File "C:\Users\hardcase1\.virtualenvs\series-EAOB5IHD\lib\site-packages\django\core\handlers\exception.py", line 47, in inner
    response = get_response(request)
  File "C:\Users\hardcase1\.virtualenvs\series-EAOB5IHD\lib\site-packages\django\core\handlers\base.py", line 179, in _get_response
    response = wrapped_callback(request, *callback_args, **callback_kwargs)
  File "C:\Users\hardcase1\.virtualenvs\series-EAOB5IHD\lib\site-packages\django\views\decorators\csrf.py", line 54, in wrapped_view
    return view_func(*args, **kwargs)
  File "C:\Users\hardcase1\.virtualenvs\series-EAOB5IHD\lib\site-packages\django\views\generic\base.py", line 73, in view
    return self.dispatch(request, *args, **kwargs)
  File "C:\Users\hardcase1\.virtualenvs\series-EAOB5IHD\lib\site-packages\rest_framework\views.py", line 505, in dispatch
    response = self.handle_exception(exc)
  File "C:\Users\hardcase1\.virtualenvs\series-EAOB5IHD\lib\site-packages\rest_framework\views.py", line 465, in handle_exception
    self.raise_uncaught_exception(exc)
  File "C:\Users\hardcase1\.virtualenvs\series-EAOB5IHD\lib\site-packages\rest_framework\views.py", line 476, in raise_uncaught_exception
    raise exc
  File "C:\Users\hardcase1\.virtualenvs\series-EAOB5IHD\lib\site-packages\rest_framework\views.py", line 502, in dispatch
    response = handler(request, *args, **kwargs)
  File "C:\Users\hardcase1\.virtualenvs\series-EAOB5IHD\lib\site-packages\rest_framework\generics.py", line 199, in get
    return self.list(request, *args, **kwargs)
  File "C:\Users\hardcase1\.virtualenvs\series-EAOB5IHD\lib\site-packages\rest_framework\mixins.py", line 40, in list
    page = self.paginate_queryset(queryset)
  File "C:\Users\hardcase1\.virtualenvs\series-EAOB5IHD\lib\site-packages\rest_framework\generics.py", line 171, in paginate_queryset
    return self.paginator.paginate_queryset(queryset, self.request, view=self)
  File "C:\Users\hardcase1\.virtualenvs\series-EAOB5IHD\lib\site-packages\rest_framework\pagination.py", line 373, in paginate_queryset
    self.count = self.get_count(queryset)
  File "C:\Users\hardcase1\.virtualenvs\series-EAOB5IHD\lib\site-packages\rest_framework\pagination.py", line 512, in get_count
    return len(queryset)
  File "C:\Users\hardcase1\.virtualenvs\series-EAOB5IHD\lib\site-packages\django\db\models\query.py", line 269, in __len__
    self._fetch_all()
  File "C:\Users\hardcase1\.virtualenvs\series-EAOB5IHD\lib\site-packages\django\db\models\query.py", line 1303, in _fetch_all
    self._result_cache = list(self._iterable_class(self))
  File "C:\Users\hardcase1\.virtualenvs\series-EAOB5IHD\lib\site-packages\django\db\models\query.py", line 53, in __iter__
    results = compiler.execute_sql(chunked_fetch=self.chunked_fetch, chunk_size=self.chunk_size)
  File "C:\Users\hardcase1\.virtualenvs\series-EAOB5IHD\lib\site-packages\django\db\models\sql\compiler.py", line 1141, in execute_sql
    sql, params = self.as_sql()
  File "C:\Users\hardcase1\.virtualenvs\series-EAOB5IHD\lib\site-packages\django\db\models\sql\compiler.py", line 498, in as_sql
    extra_select, order_by, group_by = self.pre_sql_setup()
  File "C:\Users\hardcase1\.virtualenvs\series-EAOB5IHD\lib\site-packages\django\db\models\sql\compiler.py", line 55, in pre_sql_setup
    self.setup_query()
  File "C:\Users\hardcase1\.virtualenvs\series-EAOB5IHD\lib\site-packages\django\db\models\sql\compiler.py", line 46, in setup_query
    self.select, self.klass_info, self.annotation_col_map = self.get_select()
  File "C:\Users\hardcase1\.virtualenvs\series-EAOB5IHD\lib\site-packages\django\db\models\sql\compiler.py", line 267, in get_select
    sql, params = col.select_format(self, sql, params)
  File "C:\Users\hardcase1\.virtualenvs\series-EAOB5IHD\lib\site-packages\django\db\models\expressions.py", line 387, in select_format
    return self.output_field.select_format(compiler, sql, params)
TypeError: select_format() missing 1 required positional argument: 'params'
ERROR || 2020-08-07 17:32:12,579 || basehttp || "GET /user-resources/operations-history/ HTTP/1.1" 500 225555
