ERROR || 2020-07-16 13:59:30,363 || log || Internal Server Error: /archives/tvseries/9/seasons/105/
Traceback (most recent call last):
  File "C:\Users\hardcase1\.virtualenvs\series-EAOB5IHD\lib\site-packages\django\core\handlers\exception.py", line 34, in inner
    response = get_response(request)
  File "C:\Users\hardcase1\.virtualenvs\series-EAOB5IHD\lib\site-packages\django\core\handlers\base.py", line 115, in _get_response
    response = self.process_exception_by_middleware(e, request)
  File "C:\Users\hardcase1\.virtualenvs\series-EAOB5IHD\lib\site-packages\django\core\handlers\base.py", line 113, in _get_response
    response = wrapped_callback(request, *callback_args, **callback_kwargs)
  File "C:\Users\hardcase1\.virtualenvs\series-EAOB5IHD\lib\site-packages\django\views\decorators\csrf.py", line 54, in wrapped_view
    return view_func(*args, **kwargs)
  File "C:\Users\hardcase1\.virtualenvs\series-EAOB5IHD\lib\site-packages\rest_framework\viewsets.py", line 114, in view
    return self.dispatch(request, *args, **kwargs)
  File "C:\Users\hardcase1\PycharmProjects\series\archives\views.py", line 228, in dispatch
    return super().dispatch(request, *args, **kwargs)
  File "C:\Users\hardcase1\.virtualenvs\series-EAOB5IHD\lib\site-packages\rest_framework\views.py", line 505, in dispatch
    response = self.handle_exception(exc)
  File "C:\Users\hardcase1\.virtualenvs\series-EAOB5IHD\lib\site-packages\rest_framework\views.py", line 465, in handle_exception
    self.raise_uncaught_exception(exc)
  File "C:\Users\hardcase1\.virtualenvs\series-EAOB5IHD\lib\site-packages\rest_framework\views.py", line 476, in raise_uncaught_exception
    raise exc
  File "C:\Users\hardcase1\.virtualenvs\series-EAOB5IHD\lib\site-packages\rest_framework\views.py", line 502, in dispatch
    response = handler(request, *args, **kwargs)
  File "C:\Users\hardcase1\.virtualenvs\series-EAOB5IHD\lib\site-packages\rest_framework\mixins.py", line 55, in retrieve
    serializer = self.get_serializer(instance)
  File "C:\Users\hardcase1\.virtualenvs\series-EAOB5IHD\lib\site-packages\rest_framework\generics.py", line 110, in get_serializer
    return serializer_class(*args, **kwargs)
  File "C:\Users\hardcase1\PycharmProjects\series\series\helpers\serializer_mixins.py", line 86, in __init__
    _fields = MappingProxyType(self.fields)
  File "C:\Users\hardcase1\.virtualenvs\series-EAOB5IHD\lib\site-packages\django\utils\functional.py", line 48, in __get__
    res = instance.__dict__[self.name] = self.func(instance)
  File "C:\Users\hardcase1\.virtualenvs\series-EAOB5IHD\lib\site-packages\rest_framework\serializers.py", line 363, in fields
    for key, value in self.get_fields().items():
  File "C:\Users\hardcase1\PycharmProjects\series\archives\serializers.py", line 301, in get_fields
    entry_author = self.validated_data['entry_author']
  File "C:\Users\hardcase1\.virtualenvs\series-EAOB5IHD\lib\site-packages\rest_framework\serializers.py", line 278, in validated_data
    raise AssertionError(msg)
AssertionError: You must call `.is_valid()` before accessing `.validated_data`.
ERROR || 2020-07-16 13:59:30,462 || basehttp || "GET /archives/tvseries/9/seasons/105/ HTTP/1.1" 500 152922
